Workbook

Sheet Instructions
A1: 24-Month Cash Flow Forecast Model – Aurelia Developments LLC
A3: Purpose | B3: Institutional-quality monthly cash flow forecast for a Dubai luxury real estate developer, built for FP&A, private equity diligence, treasury planning, and project finance review.
A5: Color coding | B5: Blue font = hard-coded inputs; Black font = formulas; Green font = links from other sheets; Grey fill = headers/static labels; Light yellow fill = scenario toggle inputs.
A7: Model structure | B7: 1) Scenario Toggle 2) Assumptions 3) Project Database 4) Operating Schedules 5) Financing Schedules 6) Consolidated Cash Flow 7) Liquidity 8) Sensitivity 9) Dashboard
A9: How to use | B9: Select Base Case / Downside Case / Upside Case on the Scenario Toggle sheet. Update only blue-font assumption cells. All monthly schedules and outputs will update automatically.
A11: Output horizon | B11: Monthly forecast covering Apr-26 to Mar-28 (24 months).
A13: Checks | B13: The model contains schedule links, debt roll-forward logic, cash roll-forward logic, escrow mechanics, and liquidity outputs intended to mimic a PE / lender review model.

Sheet Scenario Toggle
A1: Scenario Control Panel
A3: Active Scenario | B3: Base Case
A4: Description | B4: Select scenario from dropdown. All key drivers below flow into Assumptions.
A6: Scenario Multipliers
A7: Driver | B7: Base Case | C7: Downside Case | D7: Upside Case | E7: Selected Value | F7: Unit
A8: Sales velocity multiplier | B8: 1 | C8: 0.8 | D8: 1.15 | E8: =IF($B$3="Base Case",B8,IF($B$3="Downside Case",C8,D8)) -> 1 | F8: x
A9: Sales price growth p.m. | B9: 0.004 | C9: 0.001 | D9: 0.006 | E9: =IF($B$3="Base Case",B9,IF($B$3="Downside Case",C9,D9)) -> 0.004 | F9: %
A10: Cancellation rate | B10: 0.02 | C10: 0.05 | D10: 0.01 | E10: =IF($B$3="Base Case",B10,IF($B$3="Downside Case",C10,D10)) -> 0.02 | F10: %
A11: Construction cost overrun | B11: 0 | C11: 0.08 | D11: -0.01 | E11: =IF($B$3="Base Case",B11,IF($B$3="Downside Case",C11,D11)) -> 0 | F11: %
A12: Construction delay (months) | B12: 0 | C12: 3 | D12: 0 | E12: =IF($B$3="Base Case",B12,IF($B$3="Downside Case",C12,D12)) -> 0 | F12: months
A13: Interest rate premium | B13: 0 | C13: 0.01 | D13: -0.005 | E13: =IF($B$3="Base Case",B13,IF($B$3="Downside Case",C13,D13)) -> 0 | F13: %
A14: Rent / hospitality multiplier | B14: 1 | C14: 0.9 | D14: 1.08 | E14: =IF($B$3="Base Case",B14,IF($B$3="Downside Case",C14,D14)) -> 1 | F14: x

Sheet Assumptions
A1: Assumptions
A3: Macro Assumptions
A4: Assumption | B4: Base | C4: Downside | D4: Upside | E4: Selected | F4: Unit | G4: Source / Note
A5: Inflation p.a. | B5: 0.025 | C5: 0.035 | D5: 0.02 | E5: =IF('Scenario Toggle'!$B$3="Base Case",B5,IF('Scenario Toggle'!$B$3="Downside Case",C5,D5)) -> 0.025 | F5: % | G5: Illustrative management planning assumption
A6: Construction cost escalation p.a. | B6: 0.03 | C6: 0.07 | D6: 0.02 | E6: =IF('Scenario Toggle'!$B$3="Base Case",B6,IF('Scenario Toggle'!$B$3="Downside Case",C6,D6)) -> 0.03 | F6: % | G6: Illustrative
A7: Base borrowing rate p.a. | B7: 0.065 | C7: 0.065 | D7: 0.065 | E7: =IF('Scenario Toggle'!$B$3="Base Case",B7,IF('Scenario Toggle'!$B$3="Downside Case",C7,D7)) -> 0.065 | F7: % | G7: Illustrative
A8: FX AED/USD | B8: 3.6725 | C8: 3.6725 | D8: 3.6725 | E8: =IF('Scenario Toggle'!$B$3="Base Case",B8,IF('Scenario Toggle'!$B$3="Downside Case",C8,D8)) -> 3.6725 | F8: x | G8: AED peg
A9: Minimum cash threshold | B9: 75000000 | C9: 100000000 | D9: 75000000 | E9: =IF('Scenario Toggle'!$B$3="Base Case",B9,IF('Scenario Toggle'!$B$3="Downside Case",C9,D9)) -> 75000000 | F9: AED | G9: Treasury policy
A10: Undrawn corporate revolver | B10: 250000000 | C10: 200000000 | D10: 300000000 | E10: =IF('Scenario Toggle'!$B$3="Base Case",B10,IF('Scenario Toggle'!$B$3="Downside Case",C10,D10)) -> 250000000 | F10: AED | G10: Available liquidity support
A12: Sales Assumptions
A13: Assumption | B13: Base | C13: Downside | D13: Upside | E13: Selected | F13: Unit | G13: Source / Note
A14: Booking payment | B14: 0.2 | C14: 0.2 | D14: 0.2 | E14: =IF('Scenario Toggle'!$B$3="Base Case",B14,IF('Scenario Toggle'!$B$3="Downside Case",C14,D14)) -> 0.2 | F14: % | G14: Dubai off-plan
A15: Milestone 1 payment | B15: 0.2 | C15: 0.2 | D15: 0.2 | E15: =IF('Scenario Toggle'!$B$3="Base Case",B15,IF('Scenario Toggle'!$B$3="Downside Case",C15,D15)) -> 0.2 | F15: % | G15: 6 months after sale
A16: Milestone 2 payment | B16: 0.2 | C16: 0.2 | D16: 0.2 | E16: =IF('Scenario Toggle'!$B$3="Base Case",B16,IF('Scenario Toggle'!$B$3="Downside Case",C16,D16)) -> 0.2 | F16: % | G16: 12 months after sale
A17: Milestone 3 payment | B17: 0.2 | C17: 0.2 | D17: 0.2 | E17: =IF('Scenario Toggle'!$B$3="Base Case",B17,IF('Scenario Toggle'!$B$3="Downside Case",C17,D17)) -> 0.2 | F17: % | G17: 18 months after sale
A18: Handover payment | B18: 0.2 | C18: 0.2 | D18: 0.2 | E18: =IF('Scenario Toggle'!$B$3="Base Case",B18,IF('Scenario Toggle'!$B$3="Downside Case",C18,D18)) -> 0.2 | F18: % | G18: At completion / handover
A19: Monthly sales commission | B19: 0.03 | C19: 0.035 | D19: 0.028 | E19: =IF('Scenario Toggle'!$B$3="Base Case",B19,IF('Scenario Toggle'!$B$3="Downside Case",C19,D19)) -> 0.03 | F19: % | G19: As % of sales value
A20: Monthly rental growth p.a. | B20: 0.03 | C20: 0.01 | D20: 0.04 | E20: =IF('Scenario Toggle'!$B$3="Base Case",B20,IF('Scenario Toggle'!$B$3="Downside Case",C20,D20)) -> 0.03 | F20: % | G20: Portfolio rental growth
A21: Monthly hospitality growth p.a. | B21: 0.04 | C21: 0.015 | D21: 0.05 | E21: =IF('Scenario Toggle'!$B$3="Base Case",B21,IF('Scenario Toggle'!$B$3="Downside Case",C21,D21)) -> 0.04 | F21: % | G21: Hospitality revenue growth
A23: Corporate Assumptions
A24: Assumption | B24: Base | C24: Downside | D24: Upside | E24: Selected | F24: Unit | G24: Source / Note
A25: Executive salaries (monthly) | B25: 2800000 | C25: 2800000 | D25: 2800000 | E25: =IF('Scenario Toggle'!$B$3="Base Case",B25,IF('Scenario Toggle'!$B$3="Downside Case",C25,D25)) -> 2800000 | F25: AED | G25: Illustrative
A26: Employee payroll (monthly) | B26: 5200000 | C26: 5200000 | D26: 5200000 | E26: =IF('Scenario Toggle'!$B$3="Base Case",B26,IF('Scenario Toggle'!$B$3="Downside Case",C26,D26)) -> 5200000 | F26: AED | G26: Illustrative
A27: Office rent (monthly) | B27: 650000 | C27: 650000 | D27: 650000 | E27: =IF('Scenario Toggle'!$B$3="Base Case",B27,IF('Scenario Toggle'!$B$3="Downside Case",C27,D27)) -> 650000 | F27: AED | G27: Illustrative
A28: Insurance (monthly) | B28: 350000 | C28: 350000 | D28: 350000 | E28: =IF('Scenario Toggle'!$B$3="Base Case",B28,IF('Scenario Toggle'!$B$3="Downside Case",C28,D28)) -> 350000 | F28: AED | G28: Illustrative
A29: Legal & professional fees (monthly) | B29: 900000 | C29: 1100000 | D29: 850000 | E29: =IF('Scenario Toggle'!$B$3="Base Case",B29,IF('Scenario Toggle'!$B$3="Downside Case",C29,D29)) -> 900000 | F29: AED | G29: Illustrative
A30: IT costs (monthly) | B30: 450000 | C30: 500000 | D30: 450000 | E30: =IF('Scenario Toggle'!$B$3="Base Case",B30,IF('Scenario Toggle'!$B$3="Downside Case",C30,D30)) -> 450000 | F30: AED | G30: Illustrative
A31: General admin (monthly) | B31: 750000 | C31: 800000 | D31: 700000 | E31: =IF('Scenario Toggle'!$B$3="Base Case",B31,IF('Scenario Toggle'!$B$3="Downside Case",C31,D31)) -> 750000 | F31: AED | G31: Illustrative
A32: Payroll growth p.a. | B32: 0.05 | C32: 0.06 | D32: 0.045 | E32: =IF('Scenario Toggle'!$B$3="Base Case",B32,IF('Scenario Toggle'!$B$3="Downside Case",C32,D32)) -> 0.05 | F32: % | G32: Escalation
A33: Admin cost growth p.a. | B33: 0.03 | C33: 0.05 | D33: 0.025 | E33: =IF('Scenario Toggle'!$B$3="Base Case",B33,IF('Scenario Toggle'!$B$3="Downside Case",C33,D33)) -> 0.03 | F33: % | G33: Escalation

Sheet Project Database
A1: Development Project Database
A3: Project Name | B3: Location | C3: Units | D3: Launch Date | E3: Completion Date | F3: Project Budget | G3: Avg Saleable Sqft / Unit | H3: Initial ASP / Sqft | I3: Gross Margin Target | J3: Opening Escrow | K3: Opening Debt | L3: Land / Predev Spend To Date
A4: Marina Residences Tower | B4: Dubai Marina | C4: 180 | D4: 46113 | E4: 46631 | F4: 900000000 | G4: 5000 | H4: 3200 | I4: 0.15 | J4: 120000000 | K4: 220000000 | L4: 180000000
A5: Palm Waterfront Villas | B5: Palm Jumeirah | C5: 60 | D5: 46143 | E5: 46722 | F5: 650000000 | G5: 7800 | H5: 4500 | I5: 0.18 | J5: 80000000 | K5: 140000000 | L5: 160000000
A6: Downtown Branded Residences | B6: Downtown Dubai | C6: 220 | D6: 46204 | E6: 46813 | F6: 1100000000 | G6: 4200 | H6: 2900 | I6: 0.14 | J6: 150000000 | K6: 260000000 | L6: 220000000
A7: Jumeirah Mixed-Use Development | B7: Jumeirah | C7: 140 | D7: 46174 | E7: 46784 | F7: 850000000 | G7: 3900 | H7: 2600 | I7: 0.12 | J7: 100000000 | K7: 180000000 | L7: 200000000
A9: Total / Average | C9: =SUM(C4:C8) -> 600 | F9: =SUM(F4:F8) -> 3500000000 | G9: =SUM(G4:G8) -> 20900 | H9: =SUM(H4:H8) -> 13200 | I9: =AVERAGE(I4:I8) -> 0.1475 | J9: =SUM(J4:J8) -> 450000000 | K9: =SUM(K4:K8) -> 800000000 | L9: =SUM(L4:L8) -> 760000000

Sheet Sales Forecast
A1: Monthly Sales Forecast Model
A3: Project | B3: Metric | C3: 46113 | D3: 46143 | E3: 46174 | F3: 46204 | G3: 46235 | H3: 46266 | I3: 46296 | J3: 46327 | K3: 46357 | L3: 46388 | M3: 46419 | N3: 46447 | O3: 46478 | P3: 46508 | Q3: 46539 | R3: 46569 | S3: 46600 | T3: 46631 | U3: 46661 | V3: 46692 | W3: 46722 | X3: 46753 | Y3: 46784 | Z3: 46813
A4: Marina Residences Tower | B4: Units Available BOY | C4: ='Project Database'!$C$4 -> 180 | D4: =C4-C7 -> 170.2 | E4: =D4-D7 -> 160.4 | F4: =E4-E7 -> 150.6 | G4: =F4-F7 -> 140.8 | H4: =G4-G7 -> 131 | I4: =H4-H7 -> 121.2 | J4: =I4-I7 -> 111.4 | K4: =J4-J7 -> 101.6 | ... Z4: =Y4-Y7 -> 3.6
B5: Units Sold | C5: =IF(AND(C$3>='Project Database'!$D$4,C$3<=EDATE('Project Database'!$E$4,ROUND('Scenario Toggle'!$E$12,0))),MIN(ROUND('Project Database'!$C$4/MAX(1,DATEDIF('Project Database'!$D$4,EDATE('Project Database'!$E$4,ROUND('Scenario Toggle'!$E$12,0)),"m")+1)*'Scenario Toggle'!$E$8,0),C4),0) -> 10 | D5: =IF(AND(D$3>='Project Database'!$D$4,D$3<=EDATE('Project Database'!$E$4,ROUND('Scenario Toggle'!$E$12,0))),MIN(ROUND('Project Database'!$C$4/MAX(1,DATEDIF('Project Database'!$D$4,EDATE('Project Database'!$E$4,ROUND('Scenario Toggle'!$E$12,0)),"m")+1)*'Scenario Toggle'!$E$8,0),D4),0) -> 10 | E5: =IF(AND(E$3>='Project Database'!$D$4,E$3<=EDATE('Project Database'!$E$4,ROUND('Scenario Toggle'!$E$12,0))),MIN(ROUND('Project Database'!$C$4/MAX(1,DATEDIF('Project Database'!$D$4,EDATE('Project Database'!$E$4,ROUND('Scenario Toggle'!$E$12,0)),"m")+1)*'Scenario Toggle'!$E$8,0),E4),0) -> 10 | F5: =IF(AND(F$3>='Project Database'!$D$4,F$3<=EDATE('Project Database'!$E$4,ROUND('Scenario Toggle'!$E$12,0))),MIN(ROUND('Project Database'!$C$4/MAX(1,DATEDIF('Project Database'!$D$4,EDATE('Project Database'!$E$4,ROUND('Scenario Toggle'!$E$12,0)),"m")+1)*'Scenario Toggle'!$E$8,0),F4),0) -> 10 | G5: =IF(AND(G$3>='Project Database'!$D$4,G$3<=EDATE('Project Database'!$E$4,ROUND('Scenario Toggle'!$E$12,0))),MIN(ROUND('Project Database'!$C$4/MAX(1,DATEDIF('Project Database'!$D$4,EDATE('Project Database'!$E$4,ROUND('Scenario Toggle'!$E$12,0)),"m")+1)*'Scenario Toggle'!$E$8,0),G4),0) -> 10 | H5: =IF(AND(H$3>='Project Database'!$D$4,H$3<=EDATE('Project Database'!$E$4,ROUND('Scenario Toggle'!$E$12,0))),MIN(ROUND('Project Database'!$C$4/MAX(1,DATEDIF('Project Database'!$D$4,EDATE('Project Database'!$E$4,ROUND('Scenario Toggle'!$E$12,0)),"m")+1)*'Scenario Toggle'!$E$8,0),H4),0) -> 10 | I5: =IF(AND(I$3>='Project Database'!$D$4,I$3<=EDATE('Project Database'!$E$4,ROUND('Scenario Toggle'!$E$12,0))),MIN(ROUND('Project Database'!$C$4/MAX(1,DATEDIF('Project Database'!$D$4,EDATE('Project Database'!$E$4,ROUND('Scenario Toggle'!$E$12,0)),"m")+1)*'Scenario Toggle'!$E$8,0),I4),0) -> 10 | J5: =IF(AND(J$3>='Project Database'!$D$4,J$3<=EDATE('Project Database'!$E$4,ROUND('Scenario Toggle'!$E$12,0))),MIN(ROUND('Project Database'!$C$4/MAX(1,DATEDIF('Project Database'!$D$4,EDATE('Project Database'!$E$4,ROUND('Scenario Toggle'!$E$12,0)),"m")+1)*'Scenario Toggle'!$E$8,0),J4),0) -> 10 | ... Z5: =IF(AND(Z$3>='Project Database'!$D$4,Z$3<=EDATE('Project Database'!$E$4,ROUND('Scenario Toggle'!$E$12,0))),MIN(ROUND('Project Database'!$C$4/MAX(1,DATEDIF('Project Database'!$D$4,EDATE('Project Database'!$E$4,ROUND('Scenario Toggle'!$E$12,0)),"m")+1)*'Scenario Toggle'!$E$8,0),Z4),0) -> 0
B6: Cancellations | C6: =C5*'Scenario Toggle'!$E$10 -> 0.2 | D6: =D5*'Scenario Toggle'!$E$10 -> 0.2 | E6: =E5*'Scenario Toggle'!$E$10 -> 0.2 | F6: =F5*'Scenario Toggle'!$E$10 -> 0.2 | G6: =G5*'Scenario Toggle'!$E$10 -> 0.2 | H6: =H5*'Scenario Toggle'!$E$10 -> 0.2 | I6: =I5*'Scenario Toggle'!$E$10 -> 0.2 | J6: =J5*'Scenario Toggle'!$E$10 -> 0.2 | ... Z6: =Z5*'Scenario Toggle'!$E$10 -> 0
B7: Net Units Sold | C7: =MAX(0,C5-C6) -> 9.8 | D7: =MAX(0,D5-D6) -> 9.8 | E7: =MAX(0,E5-E6) -> 9.8 | F7: =MAX(0,F5-F6) -> 9.8 | G7: =MAX(0,G5-G6) -> 9.8 | H7: =MAX(0,H5-H6) -> 9.8 | I7: =MAX(0,I5-I6) -> 9.8 | J7: =MAX(0,J5-J6) -> 9.8 | ... Z7: =MAX(0,Z5-Z6) -> 0
B8: Avg Selling Price / Unit | C8: =IF(C$3<'Project Database'!$D$4,0,'Project Database'!$G$4*'Project Database'!$H$4*(1+'Scenario Toggle'!$E$9)^DATEDIF('Project Database'!$D$4,C$3,"m")) -> 16000000 | D8: =IF(D$3<'Project Database'!$D$4,0,'Project Database'!$G$4*'Project Database'!$H$4*(1+'Scenario Toggle'!$E$9)^DATEDIF('Project Database'!$D$4,D$3,"m")) -> 16064000 | E8: =IF(E$3<'Project Database'!$D$4,0,'Project Database'!$G$4*'Project Database'!$H$4*(1+'Scenario Toggle'!$E$9)^DATEDIF('Project Database'!$D$4,E$3,"m")) -> 16128256 | F8: =IF(F$3<'Project Database'!$D$4,0,'Project Database'!$G$4*'Project Database'!$H$4*(1+'Scenario Toggle'!$E$9)^DATEDIF('Project Database'!$D$4,F$3,"m")) -> 16192769 | G8: =IF(G$3<'Project Database'!$D$4,0,'Project Database'!$G$4*'Project Database'!$H$4*(1+'Scenario Toggle'!$E$9)^DATEDIF('Project Database'!$D$4,G$3,"m")) -> 16257540 | H8: =IF(H$3<'Project Database'!$D$4,0,'Project Database'!$G$4*'Project Database'!$H$4*(1+'Scenario Toggle'!$E$9)^DATEDIF('Project Database'!$D$4,H$3,"m")) -> 16322570 | I8: =IF(I$3<'Project Database'!$D$4,0,'Project Database'!$G$4*'Project Database'!$H$4*(1+'Scenario Toggle'!$E$9)^DATEDIF('Project Database'!$D$4,I$3,"m")) -> 16387861 | J8: =IF(J$3<'Project Database'!$D$4,0,'Project Database'!$G$4*'Project Database'!$H$4*(1+'Scenario Toggle'!$E$9)^DATEDIF('Project Database'!$D$4,J$3,"m")) -> 16453412 | ... Z8: =IF(Z$3<'Project Database'!$D$4,0,'Project Database'!$G$4*'Project Database'!$H$4*(1+'Scenario Toggle'!$E$9)^DATEDIF('Project Database'!$D$4,Z$3,"m")) -> 17538618
B9: Sales Value | C9: =C7*C8 -> 156800000 | D9: =D7*D8 -> 157427200 | E9: =E7*E8 -> 1.5805691e+08 | F9: =F7*F8 -> 1.5868914e+08 | G9: =G7*G8 -> 1.5932389e+08 | H9: =H7*H8 -> 1.5996119e+08 | I9: =I7*I8 -> 1.6060103e+08 | J9: =J7*J8 -> 1.6124344e+08 | ... Z9: =Z7*Z8 -> 0
A10: Palm Waterfront Villas | B10: Units Available BOY | C10: ='Project Database'!$C$5 -> 60 | D10: =C10-C13 -> 60 | E10: =D10-D13 -> 57.06 | F10: =E10-E13 -> 54.12 | G10: =F10-F13 -> 51.18 | H10: =G10-G13 -> 48.24 | I10: =H10-H13 -> 45.3 | J10: =I10-I13 -> 42.36 | K10: =J10-J13 -> 39.42 | ... Z10: =Y10-Y13 -> 1.2
B11: Units Sold | C11: =IF(AND(C$3>='Project Database'!$D$5,C$3<=EDATE('Project Database'!$E$5,ROUND('Scenario Toggle'!$E$12,0))),MIN(ROUND('Project Database'!$C$5/MAX(1,DATEDIF('Project Database'!$D$5,EDATE('Project Database'!$E$5,ROUND('Scenario Toggle'!$E$12,0)),"m")+1)*'Scenario Toggle'!$E$8,0),C10),0) -> 0 | D11: =IF(AND(D$3>='Project Database'!$D$5,D$3<=EDATE('Project Database'!$E$5,ROUND('Scenario Toggle'!$E$12,0))),MIN(ROUND('Project Database'!$C$5/MAX(1,DATEDIF('Project Database'!$D$5,EDATE('Project Database'!$E$5,ROUND('Scenario Toggle'!$E$12,0)),"m")+1)*'Scenario Toggle'!$E$8,0),D10),0) -> 3 | E11: =IF(AND(E$3>='Project Database'!$D$5,E$3<=EDATE('Project Database'!$E$5,ROUND('Scenario Toggle'!$E$12,0))),MIN(ROUND('Project Database'!$C$5/MAX(1,DATEDIF('Project Database'!$D$5,EDATE('Project Database'!$E$5,ROUND('Scenario Toggle'!$E$12,0)),"m")+1)*'Scenario Toggle'!$E$8,0),E10),0) -> 3 | F11: =IF(AND(F$3>='Project Database'!$D$5,F$3<=EDATE('Project Database'!$E$5,ROUND('Scenario Toggle'!$E$12,0))),MIN(ROUND('Project Database'!$C$5/MAX(1,DATEDIF('Project Database'!$D$5,EDATE('Project Database'!$E$5,ROUND('Scenario Toggle'!$E$12,0)),"m")+1)*'Scenario Toggle'!$E$8,0),F10),0) -> 3 | G11: =IF(AND(G$3>='Project Database'!$D$5,G$3<=EDATE('Project Database'!$E$5,ROUND('Scenario Toggle'!$E$12,0))),MIN(ROUND('Project Database'!$C$5/MAX(1,DATEDIF('Project Database'!$D$5,EDATE('Project Database'!$E$5,ROUND('Scenario Toggle'!$E$12,0)),"m")+1)*'Scenario Toggle'!$E$8,0),G10),0) -> 3 | H11: =IF(AND(H$3>='Project Database'!$D$5,H$3<=EDATE('Project Database'!$E$5,ROUND('Scenario Toggle'!$E$12,0))),MIN(ROUND('Project Database'!$C$5/MAX(1,DATEDIF('Project Database'!$D$5,EDATE('Project Database'!$E$5,ROUND('Scenario Toggle'!$E$12,0)),"m")+1)*'Scenario Toggle'!$E$8,0),H10),0) -> 3 | I11: =IF(AND(I$3>='Project Database'!$D$5,I$3<=EDATE('Project Database'!$E$5,ROUND('Scenario Toggle'!$E$12,0))),MIN(ROUND('Project Database'!$C$5/MAX(1,DATEDIF('Project Database'!$D$5,EDATE('Project Database'!$E$5,ROUND('Scenario Toggle'!$E$12,0)),"m")+1)*'Scenario Toggle'!$E$8,0),I10),0) -> 3 | J11: =IF(AND(J$3>='Project Database'!$D$5,J$3<=EDATE('Project Database'!$E$5,ROUND('Scenario Toggle'!$E$12,0))),MIN(ROUND('Project Database'!$C$5/MAX(1,DATEDIF('Project Database'!$D$5,EDATE('Project Database'!$E$5,ROUND('Scenario Toggle'!$E$12,0)),"m")+1)*'Scenario Toggle'!$E$8,0),J10),0) -> 3 | ... Z11: =IF(AND(Z$3>='Project Database'!$D$5,Z$3<=EDATE('Project Database'!$E$5,ROUND('Scenario Toggle'!$E$12,0))),MIN(ROUND('Project Database'!$C$5/MAX(1,DATEDIF('Project Database'!$D$5,EDATE('Project Database'!$E$5,ROUND('Scenario Toggle'!$E$12,0)),"m")+1)*'Scenario Toggle'!$E$8,0),Z10),0) -> 0
B12: Cancellations | C12: =C11*'Scenario Toggle'!$E$10 -> 0 | D12: =D11*'Scenario Toggle'!$E$10 -> 0.06 | E12: =E11*'Scenario Toggle'!$E$10 -> 0.06 | F12: =F11*'Scenario Toggle'!$E$10 -> 0.06 | G12: =G11*'Scenario Toggle'!$E$10 -> 0.06 | H12: =H11*'Scenario Toggle'!$E$10 -> 0.06 | I12: =I11*'Scenario Toggle'!$E$10 -> 0.06 | J12: =J11*'Scenario Toggle'!$E$10 -> 0.06 | ... Z12: =Z11*'Scenario Toggle'!$E$10 -> 0
B13: Net Units Sold | C13: =MAX(0,C11-C12) -> 0 | D13: =MAX(0,D11-D12) -> 2.94 | E13: =MAX(0,E11-E12) -> 2.94 | F13: =MAX(0,F11-F12) -> 2.94 | G13: =MAX(0,G11-G12) -> 2.94 | H13: =MAX(0,H11-H12) -> 2.94 | I13: =MAX(0,I11-I12) -> 2.94 | J13: =MAX(0,J11-J12) -> 2.94 | ... Z13: =MAX(0,Z11-Z12) -> 0
B14: Avg Selling Price / Unit | C14: =IF(C$3<'Project Database'!$D$5,0,'Project Database'!$G$5*'Project Database'!$H$5*(1+'Scenario Toggle'!$E$9)^DATEDIF('Project Database'!$D$5,C$3,"m")) -> 0 | D14: =IF(D$3<'Project Database'!$D$5,0,'Project Database'!$G$5*'Project Database'!$H$5*(1+'Scenario Toggle'!$E$9)^DATEDIF('Project Database'!$D$5,D$3,"m")) -> 35100000 | E14: =IF(E$3<'Project Database'!$D$5,0,'Project Database'!$G$5*'Project Database'!$H$5*(1+'Scenario Toggle'!$E$9)^DATEDIF('Project Database'!$D$5,E$3,"m")) -> 35240400 | F14: =IF(F$3<'Project Database'!$D$5,0,'Project Database'!$G$5*'Project Database'!$H$5*(1+'Scenario Toggle'!$E$9)^DATEDIF('Project Database'!$D$5,F$3,"m")) -> 35381362 | G14: =IF(G$3<'Project Database'!$D$5,0,'Project Database'!$G$5*'Project Database'!$H$5*(1+'Scenario Toggle'!$E$9)^DATEDIF('Project Database'!$D$5,G$3,"m")) -> 35522887 | H14: =IF(H$3<'Project Database'!$D$5,0,'Project Database'!$G$5*'Project Database'!$H$5*(1+'Scenario Toggle'!$E$9)^DATEDIF('Project Database'!$D$5,H$3,"m")) -> 35664979 | I14: =IF(I$3<'Project Database'!$D$5,0,'Project Database'!$G$5*'Project Database'!$H$5*(1+'Scenario Toggle'!$E$9)^DATEDIF('Project Database'!$D$5,I$3,"m")) -> 35807639 | J14: =IF(J$3<'Project Database'!$D$5,0,'Project Database'!$G$5*'Project Database'!$H$5*(1+'Scenario Toggle'!$E$9)^DATEDIF('Project Database'!$D$5,J$3,"m")) -> 35950869 | ... Z14: =IF(Z$3<'Project Database'!$D$5,0,'Project Database'!$G$5*'Project Database'!$H$5*(1+'Scenario Toggle'!$E$9)^DATEDIF('Project Database'!$D$5,Z$3,"m")) -> 38322056
B15: Sales Value | C15: =C13*C14 -> 0 | D15: =D13*D14 -> 103194000 | E15: =E13*E14 -> 103606776 | F15: =F13*F14 -> 1.040212e+08 | G15: =G13*G14 -> 1.0443729e+08 | H15: =H13*H14 -> 1.0485504e+08 | I15: =I13*I14 -> 1.0527446e+08 | J15: =J13*J14 -> 1.0569556e+08 | ... Z15: =Z13*Z14 -> 0
A16: Downtown Branded Residences | B16: Units Available BOY | C16: ='Project Database'!$C$6 -> 220 | D16: =C16-C19 -> 220 | E16: =D16-D19 -> 220 | F16: =E16-E19 -> 220 | G16: =F16-F19 -> 210.2 | H16: =G16-G19 -> 200.4 | I16: =H16-H19 -> 190.6 | J16: =I16-I19 -> 180.8 | K16: =J16-J19 -> 171 | ... Z16: =Y16-Y19 -> 24
B17: Units Sold | C17: =IF(AND(C$3>='Project Database'!$D$6,C$3<=EDATE('Project Database'!$E$6,ROUND('Scenario Toggle'!$E$12,0))),MIN(ROUND('Project Database'!$C$6/MAX(1,DATEDIF('Project Database'!$D$6,EDATE('Project Database'!$E$6,ROUND('Scenario Toggle'!$E$12,0)),"m")+1)*'Scenario Toggle'!$E$8,0),C16),0) -> 0 | D17: =IF(AND(D$3>='Project Database'!$D$6,D$3<=EDATE('Project Database'!$E$6,ROUND('Scenario Toggle'!$E$12,0))),MIN(ROUND('Project Database'!$C$6/MAX(1,DATEDIF('Project Database'!$D$6,EDATE('Project Database'!$E$6,ROUND('Scenario Toggle'!$E$12,0)),"m")+1)*'Scenario Toggle'!$E$8,0),D16),0) -> 0 | E17: =IF(AND(E$3>='Project Database'!$D$6,E$3<=EDATE('Project Database'!$E$6,ROUND('Scenario Toggle'!$E$12,0))),MIN(ROUND('Project Database'!$C$6/MAX(1,DATEDIF('Project Database'!$D$6,EDATE('Project Database'!$E$6,ROUND('Scenario Toggle'!$E$12,0)),"m")+1)*'Scenario Toggle'!$E$8,0),E16),0) -> 0 | F17: =IF(AND(F$3>='Project Database'!$D$6,F$3<=EDATE('Project Database'!$E$6,ROUND('Scenario Toggle'!$E$12,0))),MIN(ROUND('Project Database'!$C$6/MAX(1,DATEDIF('Project Database'!$D$6,EDATE('Project Database'!$E$6,ROUND('Scenario Toggle'!$E$12,0)),"m")+1)*'Scenario Toggle'!$E$8,0),F16),0) -> 10 | G17: =IF(AND(G$3>='Project Database'!$D$6,G$3<=EDATE('Project Database'!$E$6,ROUND('Scenario Toggle'!$E$12,0))),MIN(ROUND('Project Database'!$C$6/MAX(1,DATEDIF('Project Database'!$D$6,EDATE('Project Database'!$E$6,ROUND('Scenario Toggle'!$E$12,0)),"m")+1)*'Scenario Toggle'!$E$8,0),G16),0) -> 10 | H17: =IF(AND(H$3>='Project Database'!$D$6,H$3<=EDATE('Project Database'!$E$6,ROUND('Scenario Toggle'!$E$12,0))),MIN(ROUND('Project Database'!$C$6/MAX(1,DATEDIF('Project Database'!$D$6,EDATE('Project Database'!$E$6,ROUND('Scenario Toggle'!$E$12,0)),"m")+1)*'Scenario Toggle'!$E$8,0),H16),0) -> 10 | I17: =IF(AND(I$3>='Project Database'!$D$6,I$3<=EDATE('Project Database'!$E$6,ROUND('Scenario Toggle'!$E$12,0))),MIN(ROUND('Project Database'!$C$6/MAX(1,DATEDIF('Project Database'!$D$6,EDATE('Project Database'!$E$6,ROUND('Scenario Toggle'!$E$12,0)),"m")+1)*'Scenario Toggle'!$E$8,0),I16),0) -> 10 | J17: =IF(AND(J$3>='Project Database'!$D$6,J$3<=EDATE('Project Database'!$E$6,ROUND('Scenario Toggle'!$E$12,0))),MIN(ROUND('Project Database'!$C$6/MAX(1,DATEDIF('Project Database'!$D$6,EDATE('Project Database'!$E$6,ROUND('Scenario Toggle'!$E$12,0)),"m")+1)*'Scenario Toggle'!$E$8,0),J16),0) -> 10 | ... Z17: =IF(AND(Z$3>='Project Database'!$D$6,Z$3<=EDATE('Project Database'!$E$6,ROUND('Scenario Toggle'!$E$12,0))),MIN(ROUND('Project Database'!$C$6/MAX(1,DATEDIF('Project Database'!$D$6,EDATE('Project Database'!$E$6,ROUND('Scenario Toggle'!$E$12,0)),"m")+1)*'Scenario Toggle'!$E$8,0),Z16),0) -> 10
B18: Cancellations | C18: =C17*'Scenario Toggle'!$E$10 -> 0 | D18: =D17*'Scenario Toggle'!$E$10 -> 0 | E18: =E17*'Scenario Toggle'!$E$10 -> 0 | F18: =F17*'Scenario Toggle'!$E$10 -> 0.2 | G18: =G17*'Scenario Toggle'!$E$10 -> 0.2 | H18: =H17*'Scenario Toggle'!$E$10 -> 0.2 | I18: =I17*'Scenario Toggle'!$E$10 -> 0.2 | J18: =J17*'Scenario Toggle'!$E$10 -> 0.2 | ... Z18: =Z17*'Scenario Toggle'!$E$10 -> 0.2
B19: Net Units Sold | C19: =MAX(0,C17-C18) -> 0 | D19: =MAX(0,D17-D18) -> 0 | E19: =MAX(0,E17-E18) -> 0 | F19: =MAX(0,F17-F18) -> 9.8 | G19: =MAX(0,G17-G18) -> 9.8 | H19: =MAX(0,H17-H18) -> 9.8 | I19: =MAX(0,I17-I18) -> 9.8 | J19: =MAX(0,J17-J18) -> 9.8 | ... Z19: =MAX(0,Z17-Z18) -> 9.8
B20: Avg Selling Price / Unit | C20: =IF(C$3<'Project Database'!$D$6,0,'Project Database'!$G$6*'Project Database'!$H$6*(1+'Scenario Toggle'!$E$9)^DATEDIF('Project Database'!$D$6,C$3,"m")) -> 0 | D20: =IF(D$3<'Project Database'!$D$6,0,'Project Database'!$G$6*'Project Database'!$H$6*(1+'Scenario Toggle'!$E$9)^DATEDIF('Project Database'!$D$6,D$3,"m")) -> 0 | E20: =IF(E$3<'Project Database'!$D$6,0,'Project Database'!$G$6*'Project Database'!$H$6*(1+'Scenario Toggle'!$E$9)^DATEDIF('Project Database'!$D$6,E$3,"m")) -> 0 | F20: =IF(F$3<'Project Database'!$D$6,0,'Project Database'!$G$6*'Project Database'!$H$6*(1+'Scenario Toggle'!$E$9)^DATEDIF('Project Database'!$D$6,F$3,"m")) -> 12180000 | G20: =IF(G$3<'Project Database'!$D$6,0,'Project Database'!$G$6*'Project Database'!$H$6*(1+'Scenario Toggle'!$E$9)^DATEDIF('Project Database'!$D$6,G$3,"m")) -> 12228720 | H20: =IF(H$3<'Project Database'!$D$6,0,'Project Database'!$G$6*'Project Database'!$H$6*(1+'Scenario Toggle'!$E$9)^DATEDIF('Project Database'!$D$6,H$3,"m")) -> 12277635 | I20: =IF(I$3<'Project Database'!$D$6,0,'Project Database'!$G$6*'Project Database'!$H$6*(1+'Scenario Toggle'!$E$9)^DATEDIF('Project Database'!$D$6,I$3,"m")) -> 12326745 | J20: =IF(J$3<'Project Database'!$D$6,0,'Project Database'!$G$6*'Project Database'!$H$6*(1+'Scenario Toggle'!$E$9)^DATEDIF('Project Database'!$D$6,J$3,"m")) -> 12376052 | ... Z20: =IF(Z$3<'Project Database'!$D$6,0,'Project Database'!$G$6*'Project Database'!$H$6*(1+'Scenario Toggle'!$E$9)^DATEDIF('Project Database'!$D$6,Z$3,"m")) -> 13192331
B21: Sales Value | C21: =C19*C20 -> 0 | D21: =D19*D20 -> 0 | E21: =E19*E20 -> 0 | F21: =F19*F20 -> 1.19364e+08 | G21: =G19*G20 -> 1.1984146e+08 | H21: =H19*H20 -> 1.2032082e+08 | I21: =I19*I20 -> 1.2080211e+08 | J21: =J19*J20 -> 1.2128531e+08 | ... Z21: =Z19*Z20 -> 1.2928485e+08
A22: Jumeirah Mixed-Use Development | B22: Units Available BOY | C22: ='Project Database'!$C$7 -> 140 | D22: =C22-C25 -> 140 | E22: =D22-D25 -> 140 | F22: =E22-E25 -> 133.14 | G22: =F22-F25 -> 126.28 | H22: =G22-G25 -> 119.42 | I22: =H22-H25 -> 112.56 | J22: =I22-I25 -> 105.7 | K22: =J22-J25 -> 98.84 | ... Z22: =Y22-Y25 -> 0.056
B23: Units Sold | C23: =IF(AND(C$3>='Project Database'!$D$7,C$3<=EDATE('Project Database'!$E$7,ROUND('Scenario Toggle'!$E$12,0))),MIN(ROUND('Project Database'!$C$7/MAX(1,DATEDIF('Project Database'!$D$7,EDATE('Project Database'!$E$7,ROUND('Scenario Toggle'!$E$12,0)),"m")+1)*'Scenario Toggle'!$E$8,0),C22),0) -> 0 | D23: =IF(AND(D$3>='Project Database'!$D$7,D$3<=EDATE('Project Database'!$E$7,ROUND('Scenario Toggle'!$E$12,0))),MIN(ROUND('Project Database'!$C$7/MAX(1,DATEDIF('Project Database'!$D$7,EDATE('Project Database'!$E$7,ROUND('Scenario Toggle'!$E$12,0)),"m")+1)*'Scenario Toggle'!$E$8,0),D22),0) -> 0 | E23: =IF(AND(E$3>='Project Database'!$D$7,E$3<=EDATE('Project Database'!$E$7,ROUND('Scenario Toggle'!$E$12,0))),MIN(ROUND('Project Database'!$C$7/MAX(1,DATEDIF('Project Database'!$D$7,EDATE('Project Database'!$E$7,ROUND('Scenario Toggle'!$E$12,0)),"m")+1)*'Scenario Toggle'!$E$8,0),E22),0) -> 7 | F23: =IF(AND(F$3>='Project Database'!$D$7,F$3<=EDATE('Project Database'!$E$7,ROUND('Scenario Toggle'!$E$12,0))),MIN(ROUND('Project Database'!$C$7/MAX(1,DATEDIF('Project Database'!$D$7,EDATE('Project Database'!$E$7,ROUND('Scenario Toggle'!$E$12,0)),"m")+1)*'Scenario Toggle'!$E$8,0),F22),0) -> 7 | G23: =IF(AND(G$3>='Project Database'!$D$7,G$3<=EDATE('Project Database'!$E$7,ROUND('Scenario Toggle'!$E$12,0))),MIN(ROUND('Project Database'!$C$7/MAX(1,DATEDIF('Project Database'!$D$7,EDATE('Project Database'!$E$7,ROUND('Scenario Toggle'!$E$12,0)),"m")+1)*'Scenario Toggle'!$E$8,0),G22),0) -> 7 | H23: =IF(AND(H$3>='Project Database'!$D$7,H$3<=EDATE('Project Database'!$E$7,ROUND('Scenario Toggle'!$E$12,0))),MIN(ROUND('Project Database'!$C$7/MAX(1,DATEDIF('Project Database'!$D$7,EDATE('Project Database'!$E$7,ROUND('Scenario Toggle'!$E$12,0)),"m")+1)*'Scenario Toggle'!$E$8,0),H22),0) -> 7 | I23: =IF(AND(I$3>='Project Database'!$D$7,I$3<=EDATE('Project Database'!$E$7,ROUND('Scenario Toggle'!$E$12,0))),MIN(ROUND('Project Database'!$C$7/MAX(1,DATEDIF('Project Database'!$D$7,EDATE('Project Database'!$E$7,ROUND('Scenario Toggle'!$E$12,0)),"m")+1)*'Scenario Toggle'!$E$8,0),I22),0) -> 7 | J23: =IF(AND(J$3>='Project Database'!$D$7,J$3<=EDATE('Project Database'!$E$7,ROUND('Scenario Toggle'!$E$12,0))),MIN(ROUND('Project Database'!$C$7/MAX(1,DATEDIF('Project Database'!$D$7,EDATE('Project Database'!$E$7,ROUND('Scenario Toggle'!$E$12,0)),"m")+1)*'Scenario Toggle'!$E$8,0),J22),0) -> 7 | ... Z23: =IF(AND(Z$3>='Project Database'!$D$7,Z$3<=EDATE('Project Database'!$E$7,ROUND('Scenario Toggle'!$E$12,0))),MIN(ROUND('Project Database'!$C$7/MAX(1,DATEDIF('Project Database'!$D$7,EDATE('Project Database'!$E$7,ROUND('Scenario Toggle'!$E$12,0)),"m")+1)*'Scenario Toggle'!$E$8,0),Z22),0) -> 0
B24: Cancellations | C24: =C23*'Scenario Toggle'!$E$10 -> 0 | D24: =D23*'Scenario Toggle'!$E$10 -> 0 | E24: =E23*'Scenario Toggle'!$E$10 -> 0.14 | F24: =F23*'Scenario Toggle'!$E$10 -> 0.14 | G24: =G23*'Scenario Toggle'!$E$10 -> 0.14 | H24: =H23*'Scenario Toggle'!$E$10 -> 0.14 | I24: =I23*'Scenario Toggle'!$E$10 -> 0.14 | J24: =J23*'Scenario Toggle'!$E$10 -> 0.14 | ... Z24: =Z23*'Scenario Toggle'!$E$10 -> 0
B25: Net Units Sold | C25: =MAX(0,C23-C24) -> 0 | D25: =MAX(0,D23-D24) -> 0 | E25: =MAX(0,E23-E24) -> 6.86 | F25: =MAX(0,F23-F24) -> 6.86 | G25: =MAX(0,G23-G24) -> 6.86 | H25: =MAX(0,H23-H24) -> 6.86 | I25: =MAX(0,I23-I24) -> 6.86 | J25: =MAX(0,J23-J24) -> 6.86 | ... Z25: =MAX(0,Z23-Z24) -> 0
B26: Avg Selling Price / Unit | C26: =IF(C$3<'Project Database'!$D$7,0,'Project Database'!$G$7*'Project Database'!$H$7*(1+'Scenario Toggle'!$E$9)^DATEDIF('Project Database'!$D$7,C$3,"m")) -> 0 | D26: =IF(D$3<'Project Database'!$D$7,0,'Project Database'!$G$7*'Project Database'!$H$7*(1+'Scenario Toggle'!$E$9)^DATEDIF('Project Database'!$D$7,D$3,"m")) -> 0 | E26: =IF(E$3<'Project Database'!$D$7,0,'Project Database'!$G$7*'Project Database'!$H$7*(1+'Scenario Toggle'!$E$9)^DATEDIF('Project Database'!$D$7,E$3,"m")) -> 10140000 | F26: =IF(F$3<'Project Database'!$D$7,0,'Project Database'!$G$7*'Project Database'!$H$7*(1+'Scenario Toggle'!$E$9)^DATEDIF('Project Database'!$D$7,F$3,"m")) -> 10180560 | G26: =IF(G$3<'Project Database'!$D$7,0,'Project Database'!$G$7*'Project Database'!$H$7*(1+'Scenario Toggle'!$E$9)^DATEDIF('Project Database'!$D$7,G$3,"m")) -> 10221282 | H26: =IF(H$3<'Project Database'!$D$7,0,'Project Database'!$G$7*'Project Database'!$H$7*(1+'Scenario Toggle'!$E$9)^DATEDIF('Project Database'!$D$7,H$3,"m")) -> 10262167 | I26: =IF(I$3<'Project Database'!$D$7,0,'Project Database'!$G$7*'Project Database'!$H$7*(1+'Scenario Toggle'!$E$9)^DATEDIF('Project Database'!$D$7,I$3,"m")) -> 10303216 | J26: =IF(J$3<'Project Database'!$D$7,0,'Project Database'!$G$7*'Project Database'!$H$7*(1+'Scenario Toggle'!$E$9)^DATEDIF('Project Database'!$D$7,J$3,"m")) -> 10344429 | ... Z26: =IF(Z$3<'Project Database'!$D$7,0,'Project Database'!$G$7*'Project Database'!$H$7*(1+'Scenario Toggle'!$E$9)^DATEDIF('Project Database'!$D$7,Z$3,"m")) -> 11026709
B27: Sales Value | C27: =C25*C26 -> 0 | D27: =D25*D26 -> 0 | E27: =E25*E26 -> 69560400 | F27: =F25*F26 -> 69838642 | G27: =G25*G26 -> 70117996 | H27: =H25*H26 -> 70398468 | I27: =I25*I26 -> 70680062 | J27: =J25*J26 -> 70962782 | ... Z27: =Z25*Z26 -> 0
A29: Portfolio | B29: Total Net Units Sold | C29: =C7+C13+C19+C25 -> 9.8 | D29: =D7+D13+D19+D25 -> 12.74 | E29: =E7+E13+E19+E25 -> 19.6 | F29: =F7+F13+F19+F25 -> 29.4 | G29: =G7+G13+G19+G25 -> 29.4 | H29: =H7+H13+H19+H25 -> 29.4 | I29: =I7+I13+I19+I25 -> 29.4 | J29: =J7+J13+J19+J25 -> 29.4 | ... Z29: =Z7+Z13+Z19+Z25 -> 9.8
B30: Total Sales Value | C30: =C9+C15+C21+C27 -> 156800000 | D30: =D9+D15+D21+D27 -> 260621200 | E30: =E9+E15+E21+E27 -> 3.3122408e+08 | F30: =F9+F15+F21+F27 -> 4.5191298e+08 | G30: =G9+G15+G21+G27 -> 4.5372063e+08 | H30: =H9+H15+H21+H27 -> 4.5553552e+08 | I30: =I9+I15+I21+I27 -> 4.5735766e+08 | J30: =J9+J15+J21+J27 -> 4.5918709e+08 | ... Z30: =Z9+Z15+Z21+Z27 -> 1.2928485e+08

Sheet Collections
A1: Customer Collection Schedule
A3: Project | B3: Metric | C3: 46113 | D3: 46143 | E3: 46174 | F3: 46204 | G3: 46235 | H3: 46266 | I3: 46296 | J3: 46327 | K3: 46357 | L3: 46388 | M3: 46419 | N3: 46447 | O3: 46478 | P3: 46508 | Q3: 46539 | R3: 46569 | S3: 46600 | T3: 46631 | U3: 46661 | V3: 46692 | W3: 46722 | X3: 46753 | Y3: 46784 | Z3: 46813
A4: Marina Residences Tower | B4: Booking 20% | C4: ='Sales Forecast'!C9*Assumptions!$E$14 -> 31360000 | D4: ='Sales Forecast'!D9*Assumptions!$E$14 -> 31485440 | E4: ='Sales Forecast'!E9*Assumptions!$E$14 -> 31611382 | F4: ='Sales Forecast'!F9*Assumptions!$E$14 -> 31737827 | G4: ='Sales Forecast'!G9*Assumptions!$E$14 -> 31864779 | H4: ='Sales Forecast'!H9*Assumptions!$E$14 -> 31992238 | I4: ='Sales Forecast'!I9*Assumptions!$E$14 -> 32120207 | J4: ='Sales Forecast'!J9*Assumptions!$E$14 -> 32248687 | ... Z4: ='Sales Forecast'!Z9*Assumptions!$E$14 -> 0
B5: Milestone 1 20% | C5: 0 | D5: 0 | E5: 0 | F5: 0 | G5: 0 | H5: 0 | I5: ='Sales Forecast'!C9*Assumptions!$E$15 -> 31360000 | J5: ='Sales Forecast'!D9*Assumptions!$E$15 -> 31485440 | K5: ='Sales Forecast'!E9*Assumptions!$E$15 -> 31611382 | L5: ='Sales Forecast'!F9*Assumptions!$E$15 -> 31737827 | M5: ='Sales Forecast'!G9*Assumptions!$E$15 -> 31864779 | N5: ='Sales Forecast'!H9*Assumptions!$E$15 -> 31992238 | O5: ='Sales Forecast'!I9*Assumptions!$E$15 -> 32120207 | P5: ='Sales Forecast'!J9*Assumptions!$E$15 -> 32248687 | ... Z5: ='Sales Forecast'!T9*Assumptions!$E$15 -> 33562103
B6: Milestone 2 20% | C6: 0 | D6: 0 | E6: 0 | F6: 0 | G6: 0 | H6: 0 | I6: 0 | J6: 0 | K6: 0 | L6: 0 | M6: 0 | N6: 0 | O6: ='Sales Forecast'!C9*Assumptions!$E$16 -> 31360000 | P6: ='Sales Forecast'!D9*Assumptions!$E$16 -> 31485440 | Q6: ='Sales Forecast'!E9*Assumptions!$E$16 -> 31611382 | R6: ='Sales Forecast'!F9*Assumptions!$E$16 -> 31737827 | S6: ='Sales Forecast'!G9*Assumptions!$E$16 -> 31864779 | T6: ='Sales Forecast'!H9*Assumptions!$E$16 -> 31992238 | U6: ='Sales Forecast'!I9*Assumptions!$E$16 -> 32120207 | V6: ='Sales Forecast'!J9*Assumptions!$E$16 -> 32248687 | ... Z6: ='Sales Forecast'!N9*Assumptions!$E$16 -> 32767771
B7: Milestone 3 20% | C7: 0 | D7: 0 | E7: 0 | F7: 0 | G7: 0 | H7: 0 | I7: 0 | J7: 0 | K7: 0 | L7: 0 | M7: 0 | N7: 0 | O7: 0 | P7: 0 | Q7: 0 | R7: 0 | S7: 0 | T7: 0 | U7: ='Sales Forecast'!C9*Assumptions!$E$17 -> 31360000 | V7: ='Sales Forecast'!D9*Assumptions!$E$17 -> 31485440 | W7: ='Sales Forecast'!E9*Assumptions!$E$17 -> 31611382 | X7: ='Sales Forecast'!F9*Assumptions!$E$17 -> 31737827 | Y7: ='Sales Forecast'!G9*Assumptions!$E$17 -> 31864779 | Z7: ='Sales Forecast'!H9*Assumptions!$E$17 -> 31992238
B8: Handover 20% | C8: =IF(C$3>=EDATE('Project Database'!$E$4,ROUND('Scenario Toggle'!$E$12,0)),MAX(0,SUM('Sales Forecast'!$C$9:C9)*Assumptions!$E$18-0),0) -> 0 | D8: =IF(D$3>=EDATE('Project Database'!$E$4,ROUND('Scenario Toggle'!$E$12,0)),MAX(0,SUM('Sales Forecast'!$C$9:D9)*Assumptions!$E$18-SUM(C8)),0) -> 0 | E8: =IF(E$3>=EDATE('Project Database'!$E$4,ROUND('Scenario Toggle'!$E$12,0)),MAX(0,SUM('Sales Forecast'!$C$9:E9)*Assumptions!$E$18-SUM(C8:D8)),0) -> 0 | F8: =IF(F$3>=EDATE('Project Database'!$E$4,ROUND('Scenario Toggle'!$E$12,0)),MAX(0,SUM('Sales Forecast'!$C$9:F9)*Assumptions!$E$18-SUM(C8:E8)),0) -> 0 | G8: =IF(G$3>=EDATE('Project Database'!$E$4,ROUND('Scenario Toggle'!$E$12,0)),MAX(0,SUM('Sales Forecast'!$C$9:G9)*Assumptions!$E$18-SUM(C8:F8)),0) -> 0 | H8: =IF(H$3>=EDATE('Project Database'!$E$4,ROUND('Scenario Toggle'!$E$12,0)),MAX(0,SUM('Sales Forecast'!$C$9:H9)*Assumptions!$E$18-SUM(C8:G8)),0) -> 0 | I8: =IF(I$3>=EDATE('Project Database'!$E$4,ROUND('Scenario Toggle'!$E$12,0)),MAX(0,SUM('Sales Forecast'!$C$9:I9)*Assumptions!$E$18-SUM(C8:H8)),0) -> 0 | J8: =IF(J$3>=EDATE('Project Database'!$E$4,ROUND('Scenario Toggle'!$E$12,0)),MAX(0,SUM('Sales Forecast'!$C$9:J9)*Assumptions!$E$18-SUM(C8:I8)),0) -> 0 | K8: =IF(K$3>=EDATE('Project Database'!$E$4,ROUND('Scenario Toggle'!$E$12,0)),MAX(0,SUM('Sales Forecast'!$C$9:K9)*Assumptions!$E$18-SUM(C8:J8)),0) -> 0 | L8: =IF(L$3>=EDATE('Project Database'!$E$4,ROUND('Scenario Toggle'!$E$12,0)),MAX(0,SUM('Sales Forecast'!$C$9:L9)*Assumptions!$E$18-SUM(C8:K8)),0) -> 0 | M8: =IF(M$3>=EDATE('Project Database'!$E$4,ROUND('Scenario Toggle'!$E$12,0)),MAX(0,SUM('Sales Forecast'!$C$9:M9)*Assumptions!$E$18-SUM(C8:L8)),0) -> 0 | N8: =IF(N$3>=EDATE('Project Database'!$E$4,ROUND('Scenario Toggle'!$E$12,0)),MAX(0,SUM('Sales Forecast'!$C$9:N9)*Assumptions!$E$18-SUM(C8:M8)),0) -> 0 | O8: =IF(O$3>=EDATE('Project Database'!$E$4,ROUND('Scenario Toggle'!$E$12,0)),MAX(0,SUM('Sales Forecast'!$C$9:O9)*Assumptions!$E$18-SUM(C8:N8)),0) -> 0 | P8: =IF(P$3>=EDATE('Project Database'!$E$4,ROUND('Scenario Toggle'!$E$12,0)),MAX(0,SUM('Sales Forecast'!$C$9:P9)*Assumptions!$E$18-SUM(C8:O8)),0) -> 0 | Q8: =IF(Q$3>=EDATE('Project Database'!$E$4,ROUND('Scenario Toggle'!$E$12,0)),MAX(0,SUM('Sales Forecast'!$C$9:Q9)*Assumptions!$E$18-SUM(C8:P8)),0) -> 0 | R8: =IF(R$3>=EDATE('Project Database'!$E$4,ROUND('Scenario Toggle'!$E$12,0)),MAX(0,SUM('Sales Forecast'!$C$9:R9)*Assumptions!$E$18-SUM(C8:Q8)),0) -> 0 | S8: =IF(S$3>=EDATE('Project Database'!$E$4,ROUND('Scenario Toggle'!$E$12,0)),MAX(0,SUM('Sales Forecast'!$C$9:S9)*Assumptions!$E$18-SUM(C8:R8)),0) -> 0 | T8: =IF(T$3>=EDATE('Project Database'!$E$4,ROUND('Scenario Toggle'!$E$12,0)),MAX(0,SUM('Sales Forecast'!$C$9:T9)*Assumptions!$E$18-SUM(C8:S8)),0) -> 5.8408797e+08 | U8: =IF(U$3>=EDATE('Project Database'!$E$4,ROUND('Scenario Toggle'!$E$12,0)),MAX(0,SUM('Sales Forecast'!$C$9:U9)*Assumptions!$E$18-SUM(C8:T8)),0) -> 0 | V8: =IF(V$3>=EDATE('Project Database'!$E$4,ROUND('Scenario Toggle'!$E$12,0)),MAX(0,SUM('Sales Forecast'!$C$9:V9)*Assumptions!$E$18-SUM(C8:U8)),0) -> 0 | W8: =IF(W$3>=EDATE('Project Database'!$E$4,ROUND('Scenario Toggle'!$E$12,0)),MAX(0,SUM('Sales Forecast'!$C$9:W9)*Assumptions!$E$18-SUM(C8:V8)),0) -> 0 | X8: =IF(X$3>=EDATE('Project Database'!$E$4,ROUND('Scenario Toggle'!$E$12,0)),MAX(0,SUM('Sales Forecast'!$C$9:X9)*Assumptions!$E$18-SUM(C8:W8)),0) -> 0 | Y8: =IF(Y$3>=EDATE('Project Database'!$E$4,ROUND('Scenario Toggle'!$E$12,0)),MAX(0,SUM('Sales Forecast'!$C$9:Y9)*Assumptions!$E$18-SUM(C8:X8)),0) -> 0 | Z8: =IF(Z$3>=EDATE('Project Database'!$E$4,ROUND('Scenario Toggle'!$E$12,0)),MAX(0,SUM('Sales Forecast'!$C$9:Z9)*Assumptions!$E$18-SUM(C8:Y8)),0) -> 0
B9: Total Customer Collections | C9: =SUM(C4:C8) -> 31360000 | D9: =SUM(D4:D8) -> 31485440 | E9: =SUM(E4:E8) -> 31611382 | F9: =SUM(F4:F8) -> 31737827 | G9: =SUM(G4:G8) -> 31864779 | H9: =SUM(H4:H8) -> 31992238 | I9: =SUM(I4:I8) -> 63480207 | J9: =SUM(J4:J8) -> 63734127 | ... Z9: =SUM(Z4:Z8) -> 98322112
B10: Sales Commissions | C10: ='Sales Forecast'!C9*Assumptions!$E$19 -> 4704000 | D10: ='Sales Forecast'!D9*Assumptions!$E$19 -> 4722816 | E10: ='Sales Forecast'!E9*Assumptions!$E$19 -> 4741707.3 | F10: ='Sales Forecast'!F9*Assumptions!$E$19 -> 4760674.1 | G10: ='Sales Forecast'!G9*Assumptions!$E$19 -> 4779716.8 | H10: ='Sales Forecast'!H9*Assumptions!$E$19 -> 4798835.7 | I10: ='Sales Forecast'!I9*Assumptions!$E$19 -> 4818031 | J10: ='Sales Forecast'!J9*Assumptions!$E$19 -> 4837303.1 | ... Z10: ='Sales Forecast'!Z9*Assumptions!$E$19 -> 0
A11: Palm Waterfront Villas | B11: Booking 20% | C11: ='Sales Forecast'!C15*Assumptions!$E$14 -> 0 | D11: ='Sales Forecast'!D15*Assumptions!$E$14 -> 20638800 | E11: ='Sales Forecast'!E15*Assumptions!$E$14 -> 20721355 | F11: ='Sales Forecast'!F15*Assumptions!$E$14 -> 20804241 | G11: ='Sales Forecast'!G15*Assumptions!$E$14 -> 20887458 | H11: ='Sales Forecast'!H15*Assumptions!$E$14 -> 20971007 | I11: ='Sales Forecast'!I15*Assumptions!$E$14 -> 21054891 | J11: ='Sales Forecast'!J15*Assumptions!$E$14 -> 21139111 | ... Z11: ='Sales Forecast'!Z15*Assumptions!$E$14 -> 0
B12: Milestone 1 20% | C12: 0 | D12: 0 | E12: 0 | F12: 0 | G12: 0 | H12: 0 | I12: ='Sales Forecast'!C15*Assumptions!$E$15 -> 0 | J12: ='Sales Forecast'!D15*Assumptions!$E$15 -> 20638800 | K12: ='Sales Forecast'!E15*Assumptions!$E$15 -> 20721355 | L12: ='Sales Forecast'!F15*Assumptions!$E$15 -> 20804241 | M12: ='Sales Forecast'!G15*Assumptions!$E$15 -> 20887458 | N12: ='Sales Forecast'!H15*Assumptions!$E$15 -> 20971007 | O12: ='Sales Forecast'!I15*Assumptions!$E$15 -> 21054891 | P12: ='Sales Forecast'!J15*Assumptions!$E$15 -> 21139111 | ... Z12: ='Sales Forecast'!T15*Assumptions!$E$15 -> 22000059
B13: Milestone 2 20% | C13: 0 | D13: 0 | E13: 0 | F13: 0 | G13: 0 | H13: 0 | I13: 0 | J13: 0 | K13: 0 | L13: 0 | M13: 0 | N13: 0 | O13: ='Sales Forecast'!C15*Assumptions!$E$16 -> 0 | P13: ='Sales Forecast'!D15*Assumptions!$E$16 -> 20638800 | Q13: ='Sales Forecast'!E15*Assumptions!$E$16 -> 20721355 | R13: ='Sales Forecast'!F15*Assumptions!$E$16 -> 20804241 | S13: ='Sales Forecast'!G15*Assumptions!$E$16 -> 20887458 | T13: ='Sales Forecast'!H15*Assumptions!$E$16 -> 20971007 | U13: ='Sales Forecast'!I15*Assumptions!$E$16 -> 21054891 | V13: ='Sales Forecast'!J15*Assumptions!$E$16 -> 21139111 | ... Z13: ='Sales Forecast'!N15*Assumptions!$E$16 -> 21479372
B14: Milestone 3 20% | C14: 0 | D14: 0 | E14: 0 | F14: 0 | G14: 0 | H14: 0 | I14: 0 | J14: 0 | K14: 0 | L14: 0 | M14: 0 | N14: 0 | O14: 0 | P14: 0 | Q14: 0 | R14: 0 | S14: 0 | T14: 0 | U14: ='Sales Forecast'!C15*Assumptions!$E$17 -> 0 | V14: ='Sales Forecast'!D15*Assumptions!$E$17 -> 20638800 | W14: ='Sales Forecast'!E15*Assumptions!$E$17 -> 20721355 | X14: ='Sales Forecast'!F15*Assumptions!$E$17 -> 20804241 | Y14: ='Sales Forecast'!G15*Assumptions!$E$17 -> 20887458 | Z14: ='Sales Forecast'!H15*Assumptions!$E$17 -> 20971007
B15: Handover 20% | C15: =IF(C$3>=EDATE('Project Database'!$E$5,ROUND('Scenario Toggle'!$E$12,0)),MAX(0,SUM('Sales Forecast'!$C$15:C15)*Assumptions!$E$18-0),0) -> 0 | D15: =IF(D$3>=EDATE('Project Database'!$E$5,ROUND('Scenario Toggle'!$E$12,0)),MAX(0,SUM('Sales Forecast'!$C$15:D15)*Assumptions!$E$18-SUM(C15)),0) -> 0 | E15: =IF(E$3>=EDATE('Project Database'!$E$5,ROUND('Scenario Toggle'!$E$12,0)),MAX(0,SUM('Sales Forecast'!$C$15:E15)*Assumptions!$E$18-SUM(C15:D15)),0) -> 0 | F15: =IF(F$3>=EDATE('Project Database'!$E$5,ROUND('Scenario Toggle'!$E$12,0)),MAX(0,SUM('Sales Forecast'!$C$15:F15)*Assumptions!$E$18-SUM(C15:E15)),0) -> 0 | G15: =IF(G$3>=EDATE('Project Database'!$E$5,ROUND('Scenario Toggle'!$E$12,0)),MAX(0,SUM('Sales Forecast'!$C$15:G15)*Assumptions!$E$18-SUM(C15:F15)),0) -> 0 | H15: =IF(H$3>=EDATE('Project Database'!$E$5,ROUND('Scenario Toggle'!$E$12,0)),MAX(0,SUM('Sales Forecast'!$C$15:H15)*Assumptions!$E$18-SUM(C15:G15)),0) -> 0 | I15: =IF(I$3>=EDATE('Project Database'!$E$5,ROUND('Scenario Toggle'!$E$12,0)),MAX(0,SUM('Sales Forecast'!$C$15:I15)*Assumptions!$E$18-SUM(C15:H15)),0) -> 0 | J15: =IF(J$3>=EDATE('Project Database'!$E$5,ROUND('Scenario Toggle'!$E$12,0)),MAX(0,SUM('Sales Forecast'!$C$15:J15)*Assumptions!$E$18-SUM(C15:I15)),0) -> 0 | K15: =IF(K$3>=EDATE('Project Database'!$E$5,ROUND('Scenario Toggle'!$E$12,0)),MAX(0,SUM('Sales Forecast'!$C$15:K15)*Assumptions!$E$18-SUM(C15:J15)),0) -> 0 | L15: =IF(L$3>=EDATE('Project Database'!$E$5,ROUND('Scenario Toggle'!$E$12,0)),MAX(0,SUM('Sales Forecast'!$C$15:L15)*Assumptions!$E$18-SUM(C15:K15)),0) -> 0 | M15: =IF(M$3>=EDATE('Project Database'!$E$5,ROUND('Scenario Toggle'!$E$12,0)),MAX(0,SUM('Sales Forecast'!$C$15:M15)*Assumptions!$E$18-SUM(C15:L15)),0) -> 0 | N15: =IF(N$3>=EDATE('Project Database'!$E$5,ROUND('Scenario Toggle'!$E$12,0)),MAX(0,SUM('Sales Forecast'!$C$15:N15)*Assumptions!$E$18-SUM(C15:M15)),0) -> 0 | O15: =IF(O$3>=EDATE('Project Database'!$E$5,ROUND('Scenario Toggle'!$E$12,0)),MAX(0,SUM('Sales Forecast'!$C$15:O15)*Assumptions!$E$18-SUM(C15:N15)),0) -> 0 | P15: =IF(P$3>=EDATE('Project Database'!$E$5,ROUND('Scenario Toggle'!$E$12,0)),MAX(0,SUM('Sales Forecast'!$C$15:P15)*Assumptions!$E$18-SUM(C15:O15)),0) -> 0 | Q15: =IF(Q$3>=EDATE('Project Database'!$E$5,ROUND('Scenario Toggle'!$E$12,0)),MAX(0,SUM('Sales Forecast'!$C$15:Q15)*Assumptions!$E$18-SUM(C15:P15)),0) -> 0 | R15: =IF(R$3>=EDATE('Project Database'!$E$5,ROUND('Scenario Toggle'!$E$12,0)),MAX(0,SUM('Sales Forecast'!$C$15:R15)*Assumptions!$E$18-SUM(C15:Q15)),0) -> 0 | S15: =IF(S$3>=EDATE('Project Database'!$E$5,ROUND('Scenario Toggle'!$E$12,0)),MAX(0,SUM('Sales Forecast'!$C$15:S15)*Assumptions!$E$18-SUM(C15:R15)),0) -> 0 | T15: =IF(T$3>=EDATE('Project Database'!$E$5,ROUND('Scenario Toggle'!$E$12,0)),MAX(0,SUM('Sales Forecast'!$C$15:T15)*Assumptions!$E$18-SUM(C15:S15)),0) -> 0 | U15: =IF(U$3>=EDATE('Project Database'!$E$5,ROUND('Scenario Toggle'!$E$12,0)),MAX(0,SUM('Sales Forecast'!$C$15:U15)*Assumptions!$E$18-SUM(C15:T15)),0) -> 0 | V15: =IF(V$3>=EDATE('Project Database'!$E$5,ROUND('Scenario Toggle'!$E$12,0)),MAX(0,SUM('Sales Forecast'!$C$15:V15)*Assumptions!$E$18-SUM(C15:U15)),0) -> 0 | W15: =IF(W$3>=EDATE('Project Database'!$E$5,ROUND('Scenario Toggle'!$E$12,0)),MAX(0,SUM('Sales Forecast'!$C$15:W15)*Assumptions!$E$18-SUM(C15:V15)),0) -> 4.2884442e+08 | X15: =IF(X$3>=EDATE('Project Database'!$E$5,ROUND('Scenario Toggle'!$E$12,0)),MAX(0,SUM('Sales Forecast'!$C$15:X15)*Assumptions!$E$18-SUM(C15:W15)),0) -> 0 | Y15: =IF(Y$3>=EDATE('Project Database'!$E$5,ROUND('Scenario Toggle'!$E$12,0)),MAX(0,SUM('Sales Forecast'!$C$15:Y15)*Assumptions!$E$18-SUM(C15:X15)),0) -> 0 | Z15: =IF(Z$3>=EDATE('Project Database'!$E$5,ROUND('Scenario Toggle'!$E$12,0)),MAX(0,SUM('Sales Forecast'!$C$15:Z15)*Assumptions!$E$18-SUM(C15:Y15)),0) -> 0
B16: Total Customer Collections | C16: =SUM(C11:C15) -> 0 | D16: =SUM(D11:D15) -> 20638800 | E16: =SUM(E11:E15) -> 20721355 | F16: =SUM(F11:F15) -> 20804241 | G16: =SUM(G11:G15) -> 20887458 | H16: =SUM(H11:H15) -> 20971007 | I16: =SUM(I11:I15) -> 21054891 | J16: =SUM(J11:J15) -> 41777911 | ... Z16: =SUM(Z11:Z15) -> 64450438
B17: Sales Commissions | C17: ='Sales Forecast'!C15*Assumptions!$E$19 -> 0 | D17: ='Sales Forecast'!D15*Assumptions!$E$19 -> 3095820 | E17: ='Sales Forecast'!E15*Assumptions!$E$19 -> 3108203.3 | F17: ='Sales Forecast'!F15*Assumptions!$E$19 -> 3120636.1 | G17: ='Sales Forecast'!G15*Assumptions!$E$19 -> 3133118.6 | H17: ='Sales Forecast'!H15*Assumptions!$E$19 -> 3145651.1 | I17: ='Sales Forecast'!I15*Assumptions!$E$19 -> 3158233.7 | J17: ='Sales Forecast'!J15*Assumptions!$E$19 -> 3170866.7 | ... Z17: ='Sales Forecast'!Z15*Assumptions!$E$19 -> 0
A18: Downtown Branded Residences | B18: Booking 20% | C18: ='Sales Forecast'!C21*Assumptions!$E$14 -> 0 | D18: ='Sales Forecast'!D21*Assumptions!$E$14 -> 0 | E18: ='Sales Forecast'!E21*Assumptions!$E$14 -> 0 | F18: ='Sales Forecast'!F21*Assumptions!$E$14 -> 23872800 | G18: ='Sales Forecast'!G21*Assumptions!$E$14 -> 23968291 | H18: ='Sales Forecast'!H21*Assumptions!$E$14 -> 24064164 | I18: ='Sales Forecast'!I21*Assumptions!$E$14 -> 24160421 | J18: ='Sales Forecast'!J21*Assumptions!$E$14 -> 24257063 | ... Z18: ='Sales Forecast'!Z21*Assumptions!$E$14 -> 25856969
B19: Milestone 1 20% | C19: 0 | D19: 0 | E19: 0 | F19: 0 | G19: 0 | H19: 0 | I19: ='Sales Forecast'!C21*Assumptions!$E$15 -> 0 | J19: ='Sales Forecast'!D21*Assumptions!$E$15 -> 0 | K19: ='Sales Forecast'!E21*Assumptions!$E$15 -> 0 | L19: ='Sales Forecast'!F21*Assumptions!$E$15 -> 23872800 | M19: ='Sales Forecast'!G21*Assumptions!$E$15 -> 23968291 | N19: ='Sales Forecast'!H21*Assumptions!$E$15 -> 24064164 | O19: ='Sales Forecast'!I21*Assumptions!$E$15 -> 24160421 | P19: ='Sales Forecast'!J21*Assumptions!$E$15 -> 24257063 | ... Z19: ='Sales Forecast'!T21*Assumptions!$E$15 -> 25244998
B20: Milestone 2 20% | C20: 0 | D20: 0 | E20: 0 | F20: 0 | G20: 0 | H20: 0 | I20: 0 | J20: 0 | K20: 0 | L20: 0 | M20: 0 | N20: 0 | O20: ='Sales Forecast'!C21*Assumptions!$E$16 -> 0 | P20: ='Sales Forecast'!D21*Assumptions!$E$16 -> 0 | Q20: ='Sales Forecast'!E21*Assumptions!$E$16 -> 0 | R20: ='Sales Forecast'!F21*Assumptions!$E$16 -> 23872800 | S20: ='Sales Forecast'!G21*Assumptions!$E$16 -> 23968291 | T20: ='Sales Forecast'!H21*Assumptions!$E$16 -> 24064164 | U20: ='Sales Forecast'!I21*Assumptions!$E$16 -> 24160421 | V20: ='Sales Forecast'!J21*Assumptions!$E$16 -> 24257063 | ... Z20: ='Sales Forecast'!N21*Assumptions!$E$16 -> 24647511
B21: Milestone 3 20% | C21: 0 | D21: 0 | E21: 0 | F21: 0 | G21: 0 | H21: 0 | I21: 0 | J21: 0 | K21: 0 | L21: 0 | M21: 0 | N21: 0 | O21: 0 | P21: 0 | Q21: 0 | R21: 0 | S21: 0 | T21: 0 | U21: ='Sales Forecast'!C21*Assumptions!$E$17 -> 0 | V21: ='Sales Forecast'!D21*Assumptions!$E$17 -> 0 | W21: ='Sales Forecast'!E21*Assumptions!$E$17 -> 0 | X21: ='Sales Forecast'!F21*Assumptions!$E$17 -> 23872800 | Y21: ='Sales Forecast'!G21*Assumptions!$E$17 -> 23968291 | Z21: ='Sales Forecast'!H21*Assumptions!$E$17 -> 24064164
B22: Handover 20% | C22: =IF(C$3>=EDATE('Project Database'!$E$6,ROUND('Scenario Toggle'!$E$12,0)),MAX(0,SUM('Sales Forecast'!$C$21:C21)*Assumptions!$E$18-0),0) -> 0 | D22: =IF(D$3>=EDATE('Project Database'!$E$6,ROUND('Scenario Toggle'!$E$12,0)),MAX(0,SUM('Sales Forecast'!$C$21:D21)*Assumptions!$E$18-SUM(C22)),0) -> 0 | E22: =IF(E$3>=EDATE('Project Database'!$E$6,ROUND('Scenario Toggle'!$E$12,0)),MAX(0,SUM('Sales Forecast'!$C$21:E21)*Assumptions!$E$18-SUM(C22:D22)),0) -> 0 | F22: =IF(F$3>=EDATE('Project Database'!$E$6,ROUND('Scenario Toggle'!$E$12,0)),MAX(0,SUM('Sales Forecast'!$C$21:F21)*Assumptions!$E$18-SUM(C22:E22)),0) -> 0 | G22: =IF(G$3>=EDATE('Project Database'!$E$6,ROUND('Scenario Toggle'!$E$12,0)),MAX(0,SUM('Sales Forecast'!$C$21:G21)*Assumptions!$E$18-SUM(C22:F22)),0) -> 0 | H22: =IF(H$3>=EDATE('Project Database'!$E$6,ROUND('Scenario Toggle'!$E$12,0)),MAX(0,SUM('Sales Forecast'!$C$21:H21)*Assumptions!$E$18-SUM(C22:G22)),0) -> 0 | I22: =IF(I$3>=EDATE('Project Database'!$E$6,ROUND('Scenario Toggle'!$E$12,0)),MAX(0,SUM('Sales Forecast'!$C$21:I21)*Assumptions!$E$18-SUM(C22:H22)),0) -> 0 | J22: =IF(J$3>=EDATE('Project Database'!$E$6,ROUND('Scenario Toggle'!$E$12,0)),MAX(0,SUM('Sales Forecast'!$C$21:J21)*Assumptions!$E$18-SUM(C22:I22)),0) -> 0 | K22: =IF(K$3>=EDATE('Project Database'!$E$6,ROUND('Scenario Toggle'!$E$12,0)),MAX(0,SUM('Sales Forecast'!$C$21:K21)*Assumptions!$E$18-SUM(C22:J22)),0) -> 0 | L22: =IF(L$3>=EDATE('Project Database'!$E$6,ROUND('Scenario Toggle'!$E$12,0)),MAX(0,SUM('Sales Forecast'!$C$21:L21)*Assumptions!$E$18-SUM(C22:K22)),0) -> 0 | M22: =IF(M$3>=EDATE('Project Database'!$E$6,ROUND('Scenario Toggle'!$E$12,0)),MAX(0,SUM('Sales Forecast'!$C$21:M21)*Assumptions!$E$18-SUM(C22:L22)),0) -> 0 | N22: =IF(N$3>=EDATE('Project Database'!$E$6,ROUND('Scenario Toggle'!$E$12,0)),MAX(0,SUM('Sales Forecast'!$C$21:N21)*Assumptions!$E$18-SUM(C22:M22)),0) -> 0 | O22: =IF(O$3>=EDATE('Project Database'!$E$6,ROUND('Scenario Toggle'!$E$12,0)),MAX(0,SUM('Sales Forecast'!$C$21:O21)*Assumptions!$E$18-SUM(C22:N22)),0) -> 0 | P22: =IF(P$3>=EDATE('Project Database'!$E$6,ROUND('Scenario Toggle'!$E$12,0)),MAX(0,SUM('Sales Forecast'!$C$21:P21)*Assumptions!$E$18-SUM(C22:O22)),0) -> 0 | Q22: =IF(Q$3>=EDATE('Project Database'!$E$6,ROUND('Scenario Toggle'!$E$12,0)),MAX(0,SUM('Sales Forecast'!$C$21:Q21)*Assumptions!$E$18-SUM(C22:P22)),0) -> 0 | R22: =IF(R$3>=EDATE('Project Database'!$E$6,ROUND('Scenario Toggle'!$E$12,0)),MAX(0,SUM('Sales Forecast'!$C$21:R21)*Assumptions!$E$18-SUM(C22:Q22)),0) -> 0 | S22: =IF(S$3>=EDATE('Project Database'!$E$6,ROUND('Scenario Toggle'!$E$12,0)),MAX(0,SUM('Sales Forecast'!$C$21:S21)*Assumptions!$E$18-SUM(C22:R22)),0) -> 0 | T22: =IF(T$3>=EDATE('Project Database'!$E$6,ROUND('Scenario Toggle'!$E$12,0)),MAX(0,SUM('Sales Forecast'!$C$21:T21)*Assumptions!$E$18-SUM(C22:S22)),0) -> 0 | U22: =IF(U$3>=EDATE('Project Database'!$E$6,ROUND('Scenario Toggle'!$E$12,0)),MAX(0,SUM('Sales Forecast'!$C$21:U21)*Assumptions!$E$18-SUM(C22:T22)),0) -> 0 | V22: =IF(V$3>=EDATE('Project Database'!$E$6,ROUND('Scenario Toggle'!$E$12,0)),MAX(0,SUM('Sales Forecast'!$C$21:V21)*Assumptions!$E$18-SUM(C22:U22)),0) -> 0 | W22: =IF(W$3>=EDATE('Project Database'!$E$6,ROUND('Scenario Toggle'!$E$12,0)),MAX(0,SUM('Sales Forecast'!$C$21:W21)*Assumptions!$E$18-SUM(C22:V22)),0) -> 0 | X22: =IF(X$3>=EDATE('Project Database'!$E$6,ROUND('Scenario Toggle'!$E$12,0)),MAX(0,SUM('Sales Forecast'!$C$21:X21)*Assumptions!$E$18-SUM(C22:W22)),0) -> 0 | Y22: =IF(Y$3>=EDATE('Project Database'!$E$6,ROUND('Scenario Toggle'!$E$12,0)),MAX(0,SUM('Sales Forecast'!$C$21:Y21)*Assumptions!$E$18-SUM(C22:X22)),0) -> 0 | Z22: =IF(Z$3>=EDATE('Project Database'!$E$6,ROUND('Scenario Toggle'!$E$12,0)),MAX(0,SUM('Sales Forecast'!$C$21:Z21)*Assumptions!$E$18-SUM(C22:Y22)),0) -> 5.2189924e+08
B23: Total Customer Collections | C23: =SUM(C18:C22) -> 0 | D23: =SUM(D18:D22) -> 0 | E23: =SUM(E18:E22) -> 0 | F23: =SUM(F18:F22) -> 23872800 | G23: =SUM(G18:G22) -> 23968291 | H23: =SUM(H18:H22) -> 24064164 | I23: =SUM(I18:I22) -> 24160421 | J23: =SUM(J18:J22) -> 24257063 | ... Z23: =SUM(Z18:Z22) -> 6.2171288e+08
B24: Sales Commissions | C24: ='Sales Forecast'!C21*Assumptions!$E$19 -> 0 | D24: ='Sales Forecast'!D21*Assumptions!$E$19 -> 0 | E24: ='Sales Forecast'!E21*Assumptions!$E$19 -> 0 | F24: ='Sales Forecast'!F21*Assumptions!$E$19 -> 3580920 | G24: ='Sales Forecast'!G21*Assumptions!$E$19 -> 3595243.7 | H24: ='Sales Forecast'!H21*Assumptions!$E$19 -> 3609624.7 | I24: ='Sales Forecast'!I21*Assumptions!$E$19 -> 3624063.2 | J24: ='Sales Forecast'!J21*Assumptions!$E$19 -> 3638559.4 | ... Z24: ='Sales Forecast'!Z21*Assumptions!$E$19 -> 3878545.4
A25: Jumeirah Mixed-Use Development | B25: Booking 20% | C25: ='Sales Forecast'!C27*Assumptions!$E$14 -> 0 | D25: ='Sales Forecast'!D27*Assumptions!$E$14 -> 0 | E25: ='Sales Forecast'!E27*Assumptions!$E$14 -> 13912080 | F25: ='Sales Forecast'!F27*Assumptions!$E$14 -> 13967728 | G25: ='Sales Forecast'!G27*Assumptions!$E$14 -> 14023599 | H25: ='Sales Forecast'!H27*Assumptions!$E$14 -> 14079694 | I25: ='Sales Forecast'!I27*Assumptions!$E$14 -> 14136012 | J25: ='Sales Forecast'!J27*Assumptions!$E$14 -> 14192556 | ... Z25: ='Sales Forecast'!Z27*Assumptions!$E$14 -> 0
B26: Milestone 1 20% | C26: 0 | D26: 0 | E26: 0 | F26: 0 | G26: 0 | H26: 0 | I26: ='Sales Forecast'!C27*Assumptions!$E$15 -> 0 | J26: ='Sales Forecast'!D27*Assumptions!$E$15 -> 0 | K26: ='Sales Forecast'!E27*Assumptions!$E$15 -> 13912080 | L26: ='Sales Forecast'!F27*Assumptions!$E$15 -> 13967728 | M26: ='Sales Forecast'!G27*Assumptions!$E$15 -> 14023599 | N26: ='Sales Forecast'!H27*Assumptions!$E$15 -> 14079694 | O26: ='Sales Forecast'!I27*Assumptions!$E$15 -> 14136012 | P26: ='Sales Forecast'!J27*Assumptions!$E$15 -> 14192556 | ... Z26: ='Sales Forecast'!T27*Assumptions!$E$15 -> 14770587
B27: Milestone 2 20% | C27: 0 | D27: 0 | E27: 0 | F27: 0 | G27: 0 | H27: 0 | I27: 0 | J27: 0 | K27: 0 | L27: 0 | M27: 0 | N27: 0 | O27: ='Sales Forecast'!C27*Assumptions!$E$16 -> 0 | P27: ='Sales Forecast'!D27*Assumptions!$E$16 -> 0 | Q27: ='Sales Forecast'!E27*Assumptions!$E$16 -> 13912080 | R27: ='Sales Forecast'!F27*Assumptions!$E$16 -> 13967728 | S27: ='Sales Forecast'!G27*Assumptions!$E$16 -> 14023599 | T27: ='Sales Forecast'!H27*Assumptions!$E$16 -> 14079694 | U27: ='Sales Forecast'!I27*Assumptions!$E$16 -> 14136012 | V27: ='Sales Forecast'!J27*Assumptions!$E$16 -> 14192556 | ... Z27: ='Sales Forecast'!N27*Assumptions!$E$16 -> 14421003
B28: Milestone 3 20% | C28: 0 | D28: 0 | E28: 0 | F28: 0 | G28: 0 | H28: 0 | I28: 0 | J28: 0 | K28: 0 | L28: 0 | M28: 0 | N28: 0 | O28: 0 | P28: 0 | Q28: 0 | R28: 0 | S28: 0 | T28: 0 | U28: ='Sales Forecast'!C27*Assumptions!$E$17 -> 0 | V28: ='Sales Forecast'!D27*Assumptions!$E$17 -> 0 | W28: ='Sales Forecast'!E27*Assumptions!$E$17 -> 13912080 | X28: ='Sales Forecast'!F27*Assumptions!$E$17 -> 13967728 | Y28: ='Sales Forecast'!G27*Assumptions!$E$17 -> 14023599 | Z28: ='Sales Forecast'!H27*Assumptions!$E$17 -> 14079694
B29: Handover 20% | C29: =IF(C$3>=EDATE('Project Database'!$E$7,ROUND('Scenario Toggle'!$E$12,0)),MAX(0,SUM('Sales Forecast'!$C$27:C27)*Assumptions!$E$18-0),0) -> 0 | D29: =IF(D$3>=EDATE('Project Database'!$E$7,ROUND('Scenario Toggle'!$E$12,0)),MAX(0,SUM('Sales Forecast'!$C$27:D27)*Assumptions!$E$18-SUM(C29)),0) -> 0 | E29: =IF(E$3>=EDATE('Project Database'!$E$7,ROUND('Scenario Toggle'!$E$12,0)),MAX(0,SUM('Sales Forecast'!$C$27:E27)*Assumptions!$E$18-SUM(C29:D29)),0) -> 0 | F29: =IF(F$3>=EDATE('Project Database'!$E$7,ROUND('Scenario Toggle'!$E$12,0)),MAX(0,SUM('Sales Forecast'!$C$27:F27)*Assumptions!$E$18-SUM(C29:E29)),0) -> 0 | G29: =IF(G$3>=EDATE('Project Database'!$E$7,ROUND('Scenario Toggle'!$E$12,0)),MAX(0,SUM('Sales Forecast'!$C$27:G27)*Assumptions!$E$18-SUM(C29:F29)),0) -> 0 | H29: =IF(H$3>=EDATE('Project Database'!$E$7,ROUND('Scenario Toggle'!$E$12,0)),MAX(0,SUM('Sales Forecast'!$C$27:H27)*Assumptions!$E$18-SUM(C29:G29)),0) -> 0 | I29: =IF(I$3>=EDATE('Project Database'!$E$7,ROUND('Scenario Toggle'!$E$12,0)),MAX(0,SUM('Sales Forecast'!$C$27:I27)*Assumptions!$E$18-SUM(C29:H29)),0) -> 0 | J29: =IF(J$3>=EDATE('Project Database'!$E$7,ROUND('Scenario Toggle'!$E$12,0)),MAX(0,SUM('Sales Forecast'!$C$27:J27)*Assumptions!$E$18-SUM(C29:I29)),0) -> 0 | K29: =IF(K$3>=EDATE('Project Database'!$E$7,ROUND('Scenario Toggle'!$E$12,0)),MAX(0,SUM('Sales Forecast'!$C$27:K27)*Assumptions!$E$18-SUM(C29:J29)),0) -> 0 | L29: =IF(L$3>=EDATE('Project Database'!$E$7,ROUND('Scenario Toggle'!$E$12,0)),MAX(0,SUM('Sales Forecast'!$C$27:L27)*Assumptions!$E$18-SUM(C29:K29)),0) -> 0 | M29: =IF(M$3>=EDATE('Project Database'!$E$7,ROUND('Scenario Toggle'!$E$12,0)),MAX(0,SUM('Sales Forecast'!$C$27:M27)*Assumptions!$E$18-SUM(C29:L29)),0) -> 0 | N29: =IF(N$3>=EDATE('Project Database'!$E$7,ROUND('Scenario Toggle'!$E$12,0)),MAX(0,SUM('Sales Forecast'!$C$27:N27)*Assumptions!$E$18-SUM(C29:M29)),0) -> 0 | O29: =IF(O$3>=EDATE('Project Database'!$E$7,ROUND('Scenario Toggle'!$E$12,0)),MAX(0,SUM('Sales Forecast'!$C$27:O27)*Assumptions!$E$18-SUM(C29:N29)),0) -> 0 | P29: =IF(P$3>=EDATE('Project Database'!$E$7,ROUND('Scenario Toggle'!$E$12,0)),MAX(0,SUM('Sales Forecast'!$C$27:P27)*Assumptions!$E$18-SUM(C29:O29)),0) -> 0 | Q29: =IF(Q$3>=EDATE('Project Database'!$E$7,ROUND('Scenario Toggle'!$E$12,0)),MAX(0,SUM('Sales Forecast'!$C$27:Q27)*Assumptions!$E$18-SUM(C29:P29)),0) -> 0 | R29: =IF(R$3>=EDATE('Project Database'!$E$7,ROUND('Scenario Toggle'!$E$12,0)),MAX(0,SUM('Sales Forecast'!$C$27:R27)*Assumptions!$E$18-SUM(C29:Q29)),0) -> 0 | S29: =IF(S$3>=EDATE('Project Database'!$E$7,ROUND('Scenario Toggle'!$E$12,0)),MAX(0,SUM('Sales Forecast'!$C$27:S27)*Assumptions!$E$18-SUM(C29:R29)),0) -> 0 | T29: =IF(T$3>=EDATE('Project Database'!$E$7,ROUND('Scenario Toggle'!$E$12,0)),MAX(0,SUM('Sales Forecast'!$C$27:T27)*Assumptions!$E$18-SUM(C29:S29)),0) -> 0 | U29: =IF(U$3>=EDATE('Project Database'!$E$7,ROUND('Scenario Toggle'!$E$12,0)),MAX(0,SUM('Sales Forecast'!$C$27:U27)*Assumptions!$E$18-SUM(C29:T29)),0) -> 0 | V29: =IF(V$3>=EDATE('Project Database'!$E$7,ROUND('Scenario Toggle'!$E$12,0)),MAX(0,SUM('Sales Forecast'!$C$27:V27)*Assumptions!$E$18-SUM(C29:U29)),0) -> 0 | W29: =IF(W$3>=EDATE('Project Database'!$E$7,ROUND('Scenario Toggle'!$E$12,0)),MAX(0,SUM('Sales Forecast'!$C$27:W27)*Assumptions!$E$18-SUM(C29:V29)),0) -> 0 | X29: =IF(X$3>=EDATE('Project Database'!$E$7,ROUND('Scenario Toggle'!$E$12,0)),MAX(0,SUM('Sales Forecast'!$C$27:X27)*Assumptions!$E$18-SUM(C29:W29)),0) -> 0 | Y29: =IF(Y$3>=EDATE('Project Database'!$E$7,ROUND('Scenario Toggle'!$E$12,0)),MAX(0,SUM('Sales Forecast'!$C$27:Y27)*Assumptions!$E$18-SUM(C29:X29)),0) -> 2.9510026e+08 | Z29: =IF(Z$3>=EDATE('Project Database'!$E$7,ROUND('Scenario Toggle'!$E$12,0)),MAX(0,SUM('Sales Forecast'!$C$27:Z27)*Assumptions!$E$18-SUM(C29:Y29)),0) -> 0
B30: Total Customer Collections | C30: =SUM(C25:C29) -> 0 | D30: =SUM(D25:D29) -> 0 | E30: =SUM(E25:E29) -> 13912080 | F30: =SUM(F25:F29) -> 13967728 | G30: =SUM(G25:G29) -> 14023599 | H30: =SUM(H25:H29) -> 14079694 | I30: =SUM(I25:I29) -> 14136012 | J30: =SUM(J25:J29) -> 14192556 | ... Z30: =SUM(Z25:Z29) -> 43271284
