Workbook

Sheet 1. Income Statement
A1: Quarterly Income Statement (Profit & Loss)
A2: Aurelia Developments LLC | Unaudited management accounts | Quarter ended 31 Dec 2025 | AED '000
A4: Financial Line Item | B4: Q4 2025 | C4: Q3 2025 | D4: FY2025 YTD
A5: Revenue
A6: Development sales | B6: ='4. Revenue Breakdown'!B9 -> 235 | C6: ='4. Revenue Breakdown'!C9 -> 180 | D6: ='4. Revenue Breakdown'!D9 -> 690
A7: Off-plan development sales | B7: ='4. Revenue Breakdown'!B14 -> 165 | C7: ='4. Revenue Breakdown'!C14 -> 150 | D7: ='4. Revenue Breakdown'!D14 -> 560
A8: Recurring leasing / partnership / other | B8: ='4. Revenue Breakdown'!B21 -> 53 | C8: ='4. Revenue Breakdown'!C21 -> 44 | D8: ='4. Revenue Breakdown'!D21 -> 176.5
A9: Revenue | B9: =SUM(B6:B8) -> 453 | C9: =SUM(C6:C8) -> 374 | D9: =SUM(D6:D8) -> 1426.5
A11: Cost of Sales
A12: Construction materials & subcontractors | B12: ='5. OpEx Breakdown'!B6 -> 196 | C12: ='5. OpEx Breakdown'!C6 -> 153 | D12: ='5. OpEx Breakdown'!D6 -> 618
A13: Main contractor progress billings / site works | B13: ='5. OpEx Breakdown'!B7 -> 56 | C13: ='5. OpEx Breakdown'!C7 -> 57 | D13: ='5. OpEx Breakdown'!D7 -> 167
A14: Land, infrastructure & site preparation | B14: ='5. OpEx Breakdown'!B8 -> 38 | C14: ='5. OpEx Breakdown'!C8 -> 35 | D14: ='5. OpEx Breakdown'!D8 -> 132
A15: Sales commissions & closing costs | B15: ='5. OpEx Breakdown'!B9 -> 19.5 | C15: ='5. OpEx Breakdown'!C9 -> 15 | D15: ='5. OpEx Breakdown'!D9 -> 57.4
A16: Leasing & hospitality direct operating costs | B16: ='5. OpEx Breakdown'!B10 -> 11.8 | C16: ='5. OpEx Breakdown'!C10 -> 10.5 | D16: ='5. OpEx Breakdown'!D10 -> 41.7
A17: Cost of Sales | B17: ='5. OpEx Breakdown'!B11 -> 321.3 | C17: ='5. OpEx Breakdown'!C11 -> 270.5 | D17: ='5. OpEx Breakdown'!D11 -> 1016.1
A18: Gross Profit | B18: =B9-B17 -> 131.7 | C18: =C9-C17 -> 103.5 | D18: =D9-D17 -> 410.4
A19: Gross Margin | B19: =IFERROR(B18/B9,0) -> 0.29072848 | C19: =IFERROR(C18/C9,0) -> 0.27673797 | D19: =IFERROR(D18/D9,0) -> 0.28769716
A21: Operating Expenses
A22: Sales & Marketing Expenses | B22: ='5. OpEx Breakdown'!B18 -> 18.8 | C22: ='5. OpEx Breakdown'!C18 -> 15.9 | D22: ='5. OpEx Breakdown'!D18 -> 67.9
A23: General & Administrative Expenses | B23: ='5. OpEx Breakdown'!B27 -> 42.5 | C23: ='5. OpEx Breakdown'!C27 -> 39.3 | D23: ='5. OpEx Breakdown'!D27 -> 161.3
A24: Total Operating Expenses before D&A | B24: ='5. OpEx Breakdown'!B33 -> 61.3 | C24: ='5. OpEx Breakdown'!C33 -> 55.2 | D24: ='5. OpEx Breakdown'!D33 -> 229.2
A25: EBITDA | B25: =B18-B24 -> 70.4 | C25: =C18-C24 -> 48.3 | D25: =D18-D24 -> 181.2
A26: EBITDA Margin | B26: =IFERROR(B25/B9,0) -> 0.15540839 | C26: =IFERROR(C25/C9,0) -> 0.12914439 | D26: =IFERROR(D25/D9,0) -> 0.12702419
A27: Depreciation & amortization | B27: ='5. OpEx Breakdown'!B31 -> 6.8 | C27: ='5. OpEx Breakdown'!C31 -> 6.4 | D27: ='5. OpEx Breakdown'!D31 -> 25.6
A28: Operating Income | B28: =B25-B27 -> 63.6 | C28: =C25-C27 -> 41.9 | D28: =D25-D27 -> 155.6
A30: Below EBITDA / Other
A31: Interest expense | B31: 12.9 | C31: 11.8 | D31: 48.6
A32: Interest income | B32: 1.4 | C32: 1.1 | D32: 4.5
A33: Income Before Tax | B33: =B28-B31+B32 -> 52.1 | C33: =C28-C31+C32 -> 31.2 | D33: =D28-D31+D32 -> 111.5
A34: Income tax expense | B34: 4 | C34: 2.6 | D34: 9.2
A35: Net Income | B35: =B33-B34 -> 48.1 | C35: =C33-C34 -> 28.6 | D35: =D33-D34 -> 102.3
A36: Net Margin | B36: =IFERROR(B35/B9,0) -> 0.10618102 | C36: =IFERROR(C35/C9,0) -> 0.076470588 | D36: =IFERROR(D35/D9,0) -> 0.071713985

Sheet 2. Balance Sheet
A1: Balance Sheet
A2: Aurelia Developments LLC | As at 31 Dec 2025 and 30 Sep 2025 | AED '000
A4: Asset / Liability Category | B4: Q4 2025 | C4: Q3 2025
A5: Assets
A6: Current Assets
A7: Cash & cash equivalents | B7: 186.5 | C7: 174.2
A8: Restricted cash | B8: 12 | C8: 12
A9: Accounts receivable | B9: 96.8 | C9: 88.2
A10: Contract assets / unbilled receivables | B10: 54 | C10: 47.5
A11: Development inventory | B11: 1084 | C11: 1021
A12: Completed units held for sale | B12: 122.5 | C12: 118.8
A13: Prepaid expenses & other current assets | B13: 24.6 | C13: 20.9
A14: Total Current Assets | B14: =SUM(B7:B13) -> 1580.4 | C14: =SUM(C7:C13) -> 1482.6
A16: Non-Current Assets
A17: Investment properties | B17: 315 | C17: 308
A18: Property & equipment | B18: 88.4 | C18: 82.7
A19: Right-of-use assets | B19: 16.8 | C19: 17.9
A20: Intangible assets | B20: 9.6 | C20: 10.1
A21: Deferred tax asset | B21: 4.2 | C21: 3.8
A22: Other non-current assets / deposits | B22: 26.5 | C22: 24.7
A23: Total Non-Current Assets | B23: =SUM(B17:B22) -> 460.5 | C23: =SUM(C17:C22) -> 447.2
A24: Total Assets | B24: =B14+B23 -> 2040.9 | C24: =C14+C23 -> 1929.8
A26: Liabilities and Equity
A27: Current Liabilities
A28: Accounts payable | B28: 214.5 | C28: 201.7
A29: Accrued construction & project liabilities | B29: 148.8 | C29: 132.4
A30: Customer deposits / contract liabilities | B30: 286 | C30: 254.5
A31: Accrued expenses & other payables | B31: 63.7 | C31: 58.6
A32: Income tax payable | B32: 6.2 | C32: 4.5
A33: Current portion of lease liabilities | B33: 2.8 | C33: 2.7
A34: Short-term debt | B34: ='8. Debt Summary'!E11 -> 97 | C34: 88
A35: Total Current Liabilities | B35: =SUM(B28:B34) -> 819 | C35: =SUM(C28:C34) -> 742.4
A37: Non-Current Liabilities
A38: Long-term debt | B38: ='8. Debt Summary'!F11 -> 624 | C38: 642
A39: Lease liabilities | B39: 14.5 | C39: 15.4
A40: Due to JV partners / related parties | B40: 98 | C40: 95
A41: Deferred revenue / retention liabilities | B41: 22 | C41: 19.5
A42: Total Non-Current Liabilities | B42: =SUM(B38:B41) -> 758.5 | C42: =SUM(C38:C41) -> 771.9
A43: Total Liabilities | B43: =B35+B42 -> 1577.5 | C43: =C35+C42 -> 1514.3
A45: Equity
...

Sheet 3. Cash Flow
A1: Cash Flow Statement
A2: Aurelia Developments LLC | Unaudited management accounts | Quarter ended 31 Dec 2025 | AED '000
A4: Cash Flow Category | B4: Q4 2025 | C4: FY2025 YTD
A5: Operating Activities
A6: Net Income | B6: ='1. Income Statement'!B35 -> 48.1 | C6: ='1. Income Statement'!D35 -> 102.3
A7: Depreciation & amortization | B7: ='1. Income Statement'!B27 -> 6.8 | C7: ='1. Income Statement'!D27 -> 25.6
A8: Provision / impairment charges | B8: 1.2 | C8: 3.5
A9: Accounts receivable | B9: ='2. Balance Sheet'!C9-'2. Balance Sheet'!B9 -> -8.6 | C9: -24.8
A10: Contract assets / unbilled receivables | B10: ='2. Balance Sheet'!C10-'2. Balance Sheet'!B10 -> -6.5 | C10: -18
A11: Development inventory | B11: ='2. Balance Sheet'!C11-'2. Balance Sheet'!B11 -> -63 | C11: -129
A12: Completed units held for sale | B12: ='2. Balance Sheet'!C12-'2. Balance Sheet'!B12 -> -3.7 | C12: -12.5
A13: Prepaid expenses & other current assets | B13: ='2. Balance Sheet'!C13-'2. Balance Sheet'!B13 -> -3.7 | C13: -6.6
A14: Accounts payable | B14: ='2. Balance Sheet'!B29-'2. Balance Sheet'!C29 -> 16.4 | C14: 24.5
A15: Accrued construction & project liabilities | B15: ='2. Balance Sheet'!B30-'2. Balance Sheet'!C30 -> 31.5 | C15: 30.8
A16: Customer deposits / contract liabilities | B16: ='2. Balance Sheet'!B31-'2. Balance Sheet'!C31 -> 5.1 | C16: 66
A17: Accrued expenses & other payables | B17: ='2. Balance Sheet'!B32-'2. Balance Sheet'!C32 -> 1.7 | C17: 11.7
A18: Income tax payable | B18: ='2. Balance Sheet'!B33-'2. Balance Sheet'!C33 -> 0.1 | C18: 4.7
A19: Net cash from operations before interest and tax | B19: =SUM(B6:B18) -> 25.4 | C19: =SUM(C6:C18) -> 78.2
A20: Interest paid | B20: -12.4 | C20: -43
A21: Income taxes paid | B21: -2 | C21: -7.4
A22: Net Cash from Operating Activities | B22: =SUM(B19:B21) -> 11 | C22: =SUM(C19:C21) -> 27.8
A24: Investing Activities
A25: Capital expenditures | B25: ='9. CapEx'!C12*-1 -> -12.5 | C25: -46.3
A26: Investment property additions | B26: -7 | C26: -29.1
A27: Intangible / other investing | B27: -0.8 | C27: -6.8
A28: Net Cash used in Investing Activities | B28: =SUM(B25:B27) -> -20.3 | C28: =SUM(C25:C27) -> -82.2
A30: Financing Activities
A31: Debt issuance | B31: 37.2 | C31: 142
A32: Debt repayment | B32: -45 | C32: -152
A33: Lease principal payments | B33: -0.8 | C33: -3.1
A34: Equity contributions | B34: 18 | C34: 104.2
A35: Member distributions / financing fees | B35: -0.5 | C35: -16.5
A36: Net Cash from / (used in) Financing Activities | B36: =SUM(B31:B35) -> 8.9 | C36: =SUM(C31:C35) -> 74.6
A37: Net Change in Cash | B37: =SUM(B22,B28,B36) -> -0.4 | C37: =SUM(C22,C28,C36) -> 20.2
A38: Beginning Cash Balance | B38: ='2. Balance Sheet'!C7 -> 174.2 | C38: 149.1
A39: Ending Cash Balance | B39: =B38+B37 -> 173.8 | C39: =C38+C37 -> 169.3
A41: Cash flow tie-out to balance sheet | B41: =B39-'2. Balance Sheet'!B7 -> -12.7 | C41: =C39-'2. Balance Sheet'!B7 -> -17.2

Sheet 4. Revenue Breakdown
A1: Revenue Breakdown by Segment
A2: Aurelia Developments LLC | Unaudited management accounts | Quarter ended 31 Dec 2025 | AED '000
A4: Revenue Segment | B4: Q4 2025 | C4: Q3 2025 | D4: FY2025 YTD
A5: Development Sales
A6: Waterfront tower unit handovers | B6: 128 | C6: 92 | D6: 358
A7: Villa community handovers | B7: 79 | C7: 65 | D7: 238
A8: Branded residences closings | B8: 28 | C8: 23 | D8: 94
A9: Subtotal Development Sales | B9: =SUM(B6:B8) -> 235 | C9: =SUM(C6:C8) -> 180 | D9: =SUM(D6:D8) -> 690
A11: Off-plan Development Sales
A12: Tower developments recognized over time | B12: 105 | C12: 96 | D12: 356
A13: Villa phases recognized over time | B13: 60 | C13: 54 | D13: 204
A14: Subtotal Off-plan Development Sales | B14: =SUM(B12:B13) -> 165 | C14: =SUM(C12:C13) -> 150 | D14: =SUM(D12:D13) -> 560
A16: Recurring / Partnership / Other Revenue
A17: Retail leasing income | B17: 18.5 | C17: 17.2 | D17: 69.3
A18: Hospitality / branded residence partnerships | B18: 26 | C18: 20 | D18: 81.5
A19: Development management & JV fees | B19: 5.8 | C19: 4.9 | D19: 18.2
A20: Other income | B20: 2.7 | C20: 1.9 | D20: 7.5
A21: Subtotal Recurring / Partnership / Other Revenue | B21: =SUM(B17:B20) -> 53 | C21: =SUM(C17:C20) -> 44 | D21: =SUM(D17:D20) -> 176.5
A23: Total Revenue | B23: =SUM(B9,B14,B21) -> 453 | C23: =SUM(C9,C14,C21) -> 374 | D23: =SUM(D9,D14,D21) -> 1426.5

Sheet 5. OpEx Breakdown
A1: Operating Expense Breakdown
A2: Aurelia Developments LLC | Unaudited management accounts | Quarter ended 31 Dec 2025 | AED '000
A4: Expense Category | B4: Q4 2025 | C4: Q3 2025 | D4: FY2025 YTD
A5: Direct Project Costs / Cost of Sales
A6: Construction materials & subcontractors | B6: 196 | C6: 153 | D6: 618
A7: Main contractor progress billings / site works | B7: 56 | C7: 57 | D7: 167
A8: Land, infrastructure & site preparation | B8: 38 | C8: 35 | D8: 132
A9: Sales commissions & closing costs | B9: 19.5 | C9: 15 | D9: 57.4
A10: Leasing & hospitality direct operating costs | B10: 11.8 | C10: 10.5 | D10: 41.7
A11: Total Direct Project Costs / Cost of Sales | B11: =SUM(B6:B10) -> 321.3 | C11: =SUM(C6:C10) -> 270.5 | D11: =SUM(D6:D10) -> 1016.1
A13: Sales & Marketing
A14: Advertising & digital media | B14: 6.2 | C14: 5.3 | D14: 22
A15: Broker incentives & channel commissions | B15: 7.3 | C15: 6.1 | D15: 26.7
A16: Show units / launches / events | B16: 3.1 | C16: 2.7 | D16: 10.5
A17: CRM, lead generation & market research | B17: 2.2 | C17: 1.8 | D17: 8.7
A18: Total Sales & Marketing | B18: =SUM(B14:B17) -> 18.8 | C18: =SUM(C14:C17) -> 15.9 | D18: =SUM(D14:D17) -> 67.9
A20: General & Administrative
A21: Payroll & benefits | B21: 26.5 | C21: 24.7 | D21: 101.8
A22: Office, utilities & facilities | B22: 5.8 | C22: 5.5 | D22: 22.1
A23: Professional fees | B23: 4.6 | C23: 3.9 | D23: 16.7
A24: Insurance | B24: 2.3 | C24: 2.2 | D24: 8.8
A25: Technology & IT | B25: 2.1 | C25: 1.9 | D25: 7.7
A26: Travel, entertainment & other G&A | B26: 1.2 | C26: 1.1 | D26: 4.2
A27: Total General & Administrative | B27: =SUM(B21:B26) -> 42.5 | C27: =SUM(C21:C26) -> 39.3 | D27: =SUM(D21:D26) -> 161.3
A29: Non-cash Operating Charges
A30: Depreciation & amortization | B30: 6.8 | C30: 6.4 | D30: 25.6
A31: Depreciation & amortization | B31: =SUM(B30:B30) -> 6.8 | C31: =SUM(C30:C30) -> 6.4 | D31: =SUM(D30:D30) -> 25.6
A33: Total Operating Expenses before D&A | B33: =B18+B27 -> 61.3 | C33: =C18+C27 -> 55.2 | D33: =D18+D27 -> 229.2
A34: Total Operating Expenses incl. D&A | B34: =B33+B31 -> 68.1 | C34: =C33+C31 -> 61.6 | D34: =D33+D31 -> 254.8

Sheet 6. Project Performance
A1: Project-Level Financial Performance
A2: Aurelia Developments LLC | Quarter ended 31 Dec 2025 | AED '000 unless otherwise noted
A4: Development Project | B4: Revenue | C4: Costs | D4: Gross Profit | E4: Gross Margin | F4: Units / Occupancy | G4: Backlog / Remaining GDV
A5: Major Development Projects
A6: Azure Marina Tower | B6: 176.5 | C6: 124.2 | D6: =B6-C6 -> 52.3 | E6: =IFERROR(D6/B6,0) -> 0.29631728 | F6: 62 | G6: 390
A7: Palm Crest Villas | B7: 131.8 | C7: 95.7 | D7: =B7-C7 -> 36.1 | E7: =IFERROR(D7/B7,0) -> 0.27389985 | F7: 24 | G7: 280
A8: Aurelia Residences by Riviera | B8: 74.2 | C8: 54.8 | D8: =B8-C8 -> 19.4 | E8: =IFERROR(D8/B8,0) -> 0.26145553 | F8: 18 | G8: 145
A9: Harbor Walk Mixed-Use District | B9: 52.5 | C9: 36.9 | D9: =B9-C9 -> 15.6 | E9: =IFERROR(D9/B9,0) -> 0.29714286 | F9: 14 | G9: 118
A10: Pearl Quay Retail Promenade | B10: 18 | C10: 9.7 | D10: =B10-C10 -> 8.3 | E10: =IFERROR(D10/B10,0) -> 0.46111111 | F10: 91 | G10: 26
A11: Total | B11: =SUM(B6:B10) -> 453 | C11: =SUM(C6:C10) -> 321.3 | D11: =SUM(D6:D10) -> 131.7 | E11: =IFERROR(D11/B11,0) -> 0.29072848 | F11: =SUM(F6:F10) -> 209 | G11: =SUM(G6:G10) -> 959
A13: Revenue tie-out to Income Statement | B13: =B11-'1. Income Statement'!B9 -> 0
A14: Cost of sales tie-out to Income Statement | B14: =C11-'1. Income Statement'!B17 -> 0

Sheet 7. Working Capital
A1: Working Capital Analysis
A2: Aurelia Developments LLC | As at 31 Dec 2025 and 30 Sep 2025 | AED '000 unless otherwise noted
A4: Working Capital Component | B4: Q4 2025 | C4: Q3 2025 | D4: Change
A5: Operating Current Assets
A6: Accounts receivable | B6: ='2. Balance Sheet'!B9 -> 96.8 | C6: ='2. Balance Sheet'!C9 -> 88.2 | D6: =B6-C6 -> 8.6
A7: Contract assets / unbilled receivables | B7: ='2. Balance Sheet'!B10 -> 54 | C7: ='2. Balance Sheet'!C10 -> 47.5 | D7: =B7-C7 -> 6.5
A8: Development inventory | B8: ='2. Balance Sheet'!B11 -> 1084 | C8: ='2. Balance Sheet'!C11 -> 1021 | D8: =B8-C8 -> 63
A9: Completed units held for sale | B9: ='2. Balance Sheet'!B12 -> 122.5 | C9: ='2. Balance Sheet'!C12 -> 118.8 | D9: =B9-C9 -> 3.7
A10: Prepaid expenses & other current assets | B10: ='2. Balance Sheet'!B13 -> 24.6 | C10: ='2. Balance Sheet'!C13 -> 20.9 | D10: =B10-C10 -> 3.7
A11: Total Operating Current Assets | B11: =SUM(B6:B10) -> 1381.9 | C11: =SUM(C6:C10) -> 1296.4 | D11: =SUM(D6:D10) -> 85.5
A13: Operating Current Liabilities
A14: Accounts payable | B14: ='2. Balance Sheet'!B29 -> 148.8 | C14: ='2. Balance Sheet'!C29 -> 132.4 | D14: =B14-C14 -> 16.4
A15: Accrued construction & project liabilities | B15: ='2. Balance Sheet'!B30 -> 286 | C15: ='2. Balance Sheet'!C30 -> 254.5 | D15: =B15-C15 -> 31.5
A16: Customer deposits / contract liabilities | B16: ='2. Balance Sheet'!B31 -> 63.7 | C16: ='2. Balance Sheet'!C31 -> 58.6 | D16: =B16-C16 -> 5.1
A17: Accrued expenses & other payables | B17: ='2. Balance Sheet'!B32 -> 6.2 | C17: ='2. Balance Sheet'!C32 -> 4.5 | D17: =B17-C17 -> 1.7
A18: Income tax payable | B18: ='2. Balance Sheet'!B33 -> 2.8 | C18: ='2. Balance Sheet'!C33 -> 2.7 | D18: =B18-C18 -> 0.1
A19: Total Operating Current Liabilities | B19: =SUM(B14:B18) -> 507.5 | C19: =SUM(C14:C18) -> 452.7 | D19: =SUM(D14:D18) -> 54.8
A21: Net Working Capital | B21: =B11-B19 -> 874.4 | C21: =C11-C19 -> 843.7 | D21: =D11-D19 -> 30.7
A23: Working Capital Metrics
A24: Receivables days | B24: =IFERROR((B6+B7)/'1. Income Statement'!B9*90,0) -> 29.960265 | C24: =IFERROR((C6+C7)/'1. Income Statement'!C9*90,0) -> 32.65508 | D24: =B24-C24 -> -2.6948153
A25: Inventory days | B25: =IFERROR((B8+B9)/'1. Income Statement'!B17*90,0) -> 337.95518 | C25: =IFERROR((C8+C9)/'1. Income Statement'!C17*90,0) -> 379.23105 | D25: =B25-C25 -> -41.275872
A26: Accounts payable days | B26: =IFERROR((B13+B14)/'1. Income Statement'!B17*90,0) -> 41.680672 | C26: =IFERROR((C13+C14)/'1. Income Statement'!C17*90,0) -> 44.051756 | D26: =B26-C26 -> -2.3710837
A27: Current ratio | B27: =IFERROR('2. Balance Sheet'!B14/'2. Balance Sheet'!B35,0) -> 1.9296703 | C27: =IFERROR('2. Balance Sheet'!C14/'2. Balance Sheet'!C35,0) -> 1.9970366 | D27: =B27-C27 -> -0.067366308
A28: Cash conversion cycle (days) | B28: =B24-B25-B26 -> -349.67559 | C28: =C24-C25-C26 -> -390.62773 | D28: =B28-C28 -> 40.95214

Sheet 8. Debt Summary
A1: Debt and Financing Summary
A2: Aurelia Developments LLC | Quarter ended 31 Dec 2025 | AED '000 unless otherwise noted
A4: Lender | B4: Loan Type | C4: Interest Rate | D4: Outstanding Balance | E4: Current Portion | F4: Non-Current Portion | G4: Maturity Date | H4: Security / Key Terms
A5: Interest-Bearing Debt Facilities
A6: Emirates NBD | B6: Secured project finance facility | C6: 0.0495 | D6: 265 | E6: 25 | F6: 240 | G6: 30 Jun 2028 | H6: Project-specific security package / DSCR ≥1.20x
A7: First Abu Dhabi Bank | B7: Corporate term loan | C7: 0.0535 | D7: 210 | E7: 20 | F7: 190 | G7: 30 Sep 2029 | H7: Corporate guarantee / leverage covenant
A8: Mashreq Bank | B8: Land acquisition bridge facility | C8: 0.061 | D8: 112 | E8: 30 | F8: 82 | G8: 15 Nov 2026 | H8: Land pledge / presales milestone tests
A9: ADCB | B9: Revolving working capital line | C9: 0.0575 | D9: 64 | E9: 12 | F9: 52 | G9: 31 Mar 2027 | H9: Receivables-backed borrowing base
A10: Dubai Islamic Bank | B10: Sukuk / mezzanine development facility | C10: 0.066 | D10: 70 | E10: 10 | F10: 60 | G10: 31 Dec 2028 | H10: Subordinated project-level covenant package
A11: Total Funded Debt | D11: =SUM(D6:D10) -> 721 | E11: =SUM(E6:E10) -> 97 | F11: =SUM(F6:F10) -> 624
A13: Weighted average interest rate | C13: =SUMPRODUCT(C6:C10,D6:D10)/SUM(D6:D10) -> 0.054763523

Sheet 9. CapEx
A1: Capital Expenditure Schedule
A2: Aurelia Developments LLC | Quarter ended 31 Dec 2025 | AED '000
A4: Project / Initiative | B4: Description | C4: CapEx This Quarter | D4: Year-to-Date CapEx | E4: FY2025 Budget | F4: % of Budget Spent
A5: Capital Investments
A6: Azure Marina Tower | B6: Enabling works, design development and façade packages | C6: 4.1 | D6: 15.4 | E6: 18 | F6: =IFERROR(D6/E6,0) -> 0.85555556
A7: Palm Crest Villas Phase II | B7: Infrastructure, landscaping and show villa enhancements | C7: 3 | D7: 11.7 | E7: 14 | F7: =IFERROR(D7/E7,0) -> 0.83571429
A8: Harbor Walk Mixed-Use District | B8: Shell & core works and retail fit-out predevelopment | C8: 2.8 | D8: 10.2 | E8: 12.5 | F8: =IFERROR(D8/E8,0) -> 0.816
A9: Branded Residences by Riviera | B9: Fit-out, FF&E and hospitality integration costs | C9: 1.2 | D9: 4.9 | E9: 6.5 | F9: =IFERROR(D9/E9,0) -> 0.75384615
A10: ERP / CRM / Digital Platforms | B10: ERP stabilization, CRM integration and analytics tools | C10: 0.9 | D10: 3.3 | E10: 4 | F10: =IFERROR(D10/E10,0) -> 0.825
A11: Sales Galleries & Show Units | B11: Temporary structures, signage and customer experience upgrades | C11: 0.5 | D11: 0.8 | E11: 1 | F11: =IFERROR(D11/E11,0) -> 0.8
A12: Total | C12: =SUM(C6:C11) -> 12.5 | D12: =SUM(D6:D11) -> 46.3 | E12: =SUM(E6:E11) -> 56 | F12: =IFERROR(D12/E12,0) -> 0.82678571

Sheet 10. Key Ratios
A1: Key Financial Ratios
A2: Aurelia Developments LLC | Quarter ended 31 Dec 2025 | Ratios based on unaudited management accounts
A4: Financial Metric | B4: Q4 2025 | C4: Q3 2025 | D4: Definition / Reference
A5: Revenue Growth | B5: =IFERROR(('1. Income Statement'!B9/'1. Income Statement'!C9)-1,0) -> 0.21122995 | C5: n/a | D5: Current quarter revenue vs. previous quarter
A6: Gross Margin | B6: ='1. Income Statement'!B19 -> 0.29072848 | C6: ='1. Income Statement'!C19 -> 0.27673797 | D6: Gross profit / revenue
A7: EBITDA Margin | B7: ='1. Income Statement'!B26 -> 0.15540839 | C7: ='1. Income Statement'!C26 -> 0.12914439 | D7: EBITDA / revenue
A8: Operating Margin | B8: =IFERROR('1. Income Statement'!B28/'1. Income Statement'!B9,0) -> 0.14039735 | C8: =IFERROR('1. Income Statement'!C28/'1. Income Statement'!C9,0) -> 0.11203209 | D8: Operating income / revenue
A9: Net Margin | B9: =IFERROR('1. Income Statement'!B35/'1. Income Statement'!B9,0) -> 0.10618102 | C9: =IFERROR('1. Income Statement'!C35/'1. Income Statement'!C9,0) -> 0.076470588 | D9: Net income / revenue
A10: Debt-to-Equity Ratio | B10: =IFERROR(('2. Balance Sheet'!B34+'2. Balance Sheet'!B38+'2. Balance Sheet'!B33+'2. Balance Sheet'!B39)/'2. Balance Sheet'!B49,0) -> 1.593224 | C10: =IFERROR(('2. Balance Sheet'!C34+'2. Balance Sheet'!C38+'2. Balance Sheet'!C33+'2. Balance Sheet'!C39)/'2. Balance Sheet'!C49,0) -> 1.8004813 | D10: Funded debt plus lease liabilities / equity
A11: Current Ratio | B11: ='7. Working Capital'!B27 -> 1.9296703 | C11: ='7. Working Capital'!C27 -> 1.9970366 | D11: Current assets / current liabilities
A12: Interest Coverage | B12: =IFERROR('1. Income Statement'!B25/'1. Income Statement'!B31,0) -> 5.4573643 | C12: =IFERROR('1. Income Statement'!C25/'1. Income Statement'!C31,0) -> 4.0932203 | D12: EBITDA / interest expense
A13: Net Debt / Annualized EBITDA | B13: =IFERROR((('2. Balance Sheet'!B34+'2. Balance Sheet'!B38+'2. Balance Sheet'!B33+'2. Balance Sheet'!B39-'2. Balance Sheet'!B7)/(4*'1. Income Statement'!B25)),0) -> 1.959517 | C13: =IFERROR((('2. Balance Sheet'!C34+'2. Balance Sheet'!C38+'2. Balance Sheet'!C33+'2. Balance Sheet'!C39-'2. Balance Sheet'!C7)/(4*'1. Income Statement'!C25)),0) -> 2.9704969 | D13: (Debt - cash) / annualized EBITDA

Sheet 11. Variance Analysis
A1: Quarterly Variance Analysis
A2: Aurelia Developments LLC | Q4 2025 vs. Q3 2025 | AED '000
A4: Financial Category | B4: Q4 2025 | C4: Q3 2025 | D4: Variance | E4: Variance % | F4: Management Commentary
A5: Revenue | B5: ='1. Income Statement'!B9 -> 453 | C5: ='1. Income Statement'!C9 -> 374 | D5: =B5-C5 -> 79 | E5: =IFERROR(D5/C5,0) -> 0.21122995 | F5: Higher handovers and stronger branded residence closings in the quarter.
A6: Cost of Sales | B6: ='1. Income Statement'!B17 -> 321.3 | C6: ='1. Income Statement'!C17 -> 270.5 | D6: =B6-C6 -> 50.8 | E6: =IFERROR(D6/C6,0) -> 0.18780037 | F6: Increase reflects delivery mix and higher construction progress billings.
A7: Gross Profit | B7: ='1. Income Statement'!B18 -> 131.7 | C7: ='1. Income Statement'!C18 -> 103.5 | D7: =B7-C7 -> 28.2 | E7: =IFERROR(D7/C7,0) -> 0.27246377 | F7: Margin benefited from project mix and better performance at Pearl Quay.
A8: Sales & Marketing | B8: ='1. Income Statement'!B22 -> 18.8 | C8: ='1. Income Statement'!C22 -> 15.9 | D8: =B8-C8 -> 2.9 | E8: =IFERROR(D8/C8,0) -> 0.18238994 | F8: Incremental spend supported launches and broker channel activity.
A9: General & Administrative | B9: ='1. Income Statement'!B23 -> 42.5 | C9: ='1. Income Statement'!C23 -> 39.3 | D9: =B9-C9 -> 3.2 | E9: =IFERROR(D9/C9,0) -> 0.081424936 | F9: Growth primarily due to headcount and advisory costs on active developments.
A10: EBITDA | B10: ='1. Income Statement'!B25 -> 70.4 | C10: ='1. Income Statement'!C25 -> 48.3 | D10: =B10-C10 -> 22.1 | E10: =IFERROR(D10/C10,0) -> 0.45755694 | F10: Operating leverage on higher revenue more than offset growth in overheads.
A11: Operating Income | B11: ='1. Income Statement'!B28 -> 63.6 | C11: ='1. Income Statement'!C28 -> 41.9 | D11: =B11-C11 -> 21.7 | E11: =IFERROR(D11/C11,0) -> 0.51789976 | F11: Improved profitability despite higher depreciation from new assets in service.
A12: Net Finance Cost | B12: =B30-B31 -> 0 | C12: =C30-C31 -> 0 | D12: =B12-C12 -> 0 | E12: =IFERROR(D12/C12,0) -> 0 | F12: Finance costs increased with larger average funded debt during the period.
A13: Net Income | B13: ='1. Income Statement'!B34 -> 4 | C13: ='1. Income Statement'!C34 -> 2.6 | D13: =B13-C13 -> 1.4 | E13: =IFERROR(D13/C13,0) -> 0.53846154 | F13: Profitability improved due to stronger delivery volumes and gross profit conversion.

Sheet 12. Dashboard
A1: Quarterly Financial Summary Dashboard
A2: Aurelia Developments LLC | Q4 2025 | Unaudited management accounts
A4: Metric | B4: Q4 2025 | C4: Q3 2025 | D4: QoQ Change | F4: Metric | G4: Q4 2025 | H4: Previous Quarter
A5: Revenue | B5: ='1. Income Statement'!B9 -> 453 | C5: ='1. Income Statement'!C9 -> 374 | D5: =B5-C5 -> 79 | F5: Total Assets | G5: ='2. Balance Sheet'!B24 -> 2040.9 | H5: ='2. Balance Sheet'!C24 -> 1929.8
A7: Gross Profit | B7: ='1. Income Statement'!B18 -> 131.7 | C7: ='1. Income Statement'!C18 -> 103.5 | D7: =B7-C7 -> 28.2 | F7: Total Debt | G7: ='8. Debt Summary'!D11 -> 721 | H7: ='2. Balance Sheet'!C34+'2. Balance Sheet'!C38 -> 730
A9: EBITDA | B9: ='1. Income Statement'!B25 -> 70.4 | C9: ='1. Income Statement'!C25 -> 48.3 | D9: =B9-C9 -> 22.1 | F9: Cash Balance | G9: ='2. Balance Sheet'!B7 -> 186.5 | H9: ='2. Balance Sheet'!C7 -> 174.2
A11: Net Income | B11: ='1. Income Statement'!B35 -> 48.1 | C11: ='1. Income Statement'!C35 -> 28.6 | D11: =B11-C11 -> 19.5 | F11: Net Working Capital | G11: ='7. Working Capital'!B21 -> 874.4 | H11: ='7. Working Capital'!C21 -> 843.7
A14: Dashboard summarizes core profitability, liquidity and leverage metrics for investor diligence review. All amounts are unaudited and presented in AED thousands.
A18: KPI | B18: Q4 2025 | C18: Q3 2025 | F18: Revenue Mix | G18: Q4 2025
A19: Revenue | B19: ='1. Income Statement'!B9 -> 453 | C19: ='1. Income Statement'!C9 -> 374 | F19: Development sales | G19: ='4. Revenue Breakdown'!B9 -> 235
A20: EBITDA | B20: ='1. Income Statement'!B25 -> 70.4 | C20: ='1. Income Statement'!C25 -> 48.3 | F20: Off-plan sales | G20: ='4. Revenue Breakdown'!B14 -> 165
A21: Net Income | B21: ='1. Income Statement'!B35 -> 48.1 | C21: ='1. Income Statement'!C35 -> 28.6 | F21: Recurring / other | G21: ='4. Revenue Breakdown'!B21 -> 53
